Workbook

Sheet Rezumat
A1: Verificarea strategiilor pe jurnalul tău
A2: 450 ture, 2026-05-05 07:00 – 2026-10-21 15:00. Miză: 1 leu pe tură, pe toate numerele strategiei ca un singur bilet.
A4: Cod | B4: Strategie | C4: Numere jucate (medie) | D4: Ture | E4: Nimeriri | F4: Nimerire % | G4: Așteptat din hazard % | H4: Diferență (pp) | I4: Cea mai lungă pauză | J4: Pauze de 8+ ture | K4: Pauze de 10+ ture | L4: Cota | M4: Profit (lei) | N4: Randament %
A5: A | B5: Numerele celor 10 reguli | C5: =AVERAGE(Ture!BL2:BL451) | D5: =COUNT(Ture!B2:B451) | E5: =SUM(Ture!BM2:BM451) | F5: =E5/D5 | G5: =C5/20 | H5: =(F5-G5)*100 | I5: =MAX(Ture!BN2:BN451) | J5: =COUNTIF(Ture!BN2:BN451,8) | K5: =COUNTIF(Ture!BN2:BN451,10) | L5: variază | M5: - | N5: -
A6: B | B6: Cele 9 propuneri | C6: =AVERAGE(Ture!BO2:BO451) | D6: =COUNT(Ture!B2:B451) | E6: =SUM(Ture!BP2:BP451) | F6: =E6/D6 | G6: =C6/20 | H6: =(F6-G6)*100 | I6: =MAX(Ture!BQ2:BQ451) | J6: =COUNTIF(Ture!BQ2:BQ451,8) | K6: =COUNTIF(Ture!BQ2:BQ451,10) | L6: 2.11 | M6: =E6*L6-D6 | N6: =M6/D6
A7: C | B7: Reguli + propuneri până la 9 | C7: =AVERAGE(Ture!BR2:BR451) | D7: =COUNT(Ture!B2:B451) | E7: =SUM(Ture!BS2:BS451) | F7: =E7/D7 | G7: =C7/20 | H7: =(F7-G7)*100 | I7: =MAX(Ture!BT2:BT451) | J7: =COUNTIF(Ture!BT2:BT451,8) | K7: =COUNTIF(Ture!BT2:BT451,10) | L7: 2.11 | M7: =E7*L7-D7 | N7: =M7/D7
A8: D | B8: Reguli + propuneri până la 10 | C8: =AVERAGE(Ture!BU2:BU451) | D8: =COUNT(Ture!B2:B451) | E8: =SUM(Ture!BV2:BV451) | F8: =E8/D8 | G8: =C8/20 | H8: =(F8-G8)*100 | I8: =MAX(Ture!BW2:BW451) | J8: =COUNTIF(Ture!BW2:BW451,8) | K8: =COUNTIF(Ture!BW2:BW451,10) | L8: 1.9 | M8: =E8*L8-D8 | N8: =M8/D8
A9: E | B9: Reguli + propuneri până la 11 | C9: =AVERAGE(Ture!BX2:BX451) | D9: =COUNT(Ture!B2:B451) | E9: =SUM(Ture!BY2:BY451) | F9: =E9/D9 | G9: =C9/20 | H9: =(F9-G9)*100 | I9: =MAX(Ture!BZ2:BZ451) | J9: =COUNTIF(Ture!BZ2:BZ451,8) | K9: =COUNTIF(Ture!BZ2:BZ451,10) | L9: 1.73 | M9: =E9*L9-D9 | N9: =M9/D9
A10: F | B10: Reguli + propuneri până la 12 | C10: =AVERAGE(Ture!CA2:CA451) | D10: =COUNT(Ture!B2:B451) | E10: =SUM(Ture!CB2:CB451) | F10: =E10/D10 | G10: =C10/20 | H10: =(F10-G10)*100 | I10: =MAX(Ture!CC2:CC451) | J10: =COUNTIF(Ture!CC2:CC451,8) | K10: =COUNTIF(Ture!CC2:CC451,10) | L10: 1.58 | M10: =E10*L10-D10 | N10: =M10/D10
A11: Comparație: numere alese la întâmplare (10.000 de simulări pe aceleași rezultate)
A12: Numere | B12: Nimerire % medie | C12: Cea mai lungă pauză (mediană) | D12: Cea mai lungă pauză: 90% din cazuri între
A13: 8 | B13: 0.39989 | C13: 10 | D13: 8 – 15
A14: 9 | B14: 0.45005489 | C14: 9 | D14: 7 – 13
A15: 10 | B15: 0.49986311 | C15: 8 | D15: 6 – 12
A16: 11 | B16: 0.54948511 | C16: 7 | D16: 5 – 10
A17: 12 | B17: 0.60026022 | C17: 6 | D17: 4 – 9
A19: Cum se citește
A20: • Nimerire %: în câte ture numărul ieșit a fost printre numerele strategiei.
A21: • Așteptat din hazard: numere jucate × 5% (o extragere 1–20 perfect aleatoare).
A22: • Pauză: câte ture la rând fără nimerire. „Pauze de 8+” numără câte serii de ratări au ajuns la 8 sau mai mult.
A23: • Cota (celulele galbene, albastre) e cea dată de tine: 9 numere 2,11 · 10 numere 1,90 · 11 numere 1,73 · 12 numere 1,58. O poți modifica; profitul se recalculează.
A24: • Profit: miză 1 leu pe tură (biletul cu toate numerele strategiei), câștig = cota × 1 leu la nimerire.
A25: • Strategiile C–F: întâi numerele regulilor (în ordinea din top, fără dubluri), apoi propunerile notebook-ului, până se adună numărul de numere.
A26: F (12) are uneori mai puțin de 12 numere, când regulile și propunerile se suprapun mult.
A27: • Top-ul regulilor la fiecare tură e calculat doar din turele anterioare (exact ce ai fi primit atunci). Sursa: top_reguli.csv și predictions_log.csv.
A28: • Foaia „Ture” are numerele fiecărei strategii (albastru = date) și formulele de nimerire și pauză.

Sheet Ture
A1: Tura (ora Italiei) | B1: Ieșit | C1: A1 | D1: A2 | E1: A3 | F1: A4 | G1: A5 | H1: A6 | I1: A7 | J1: A8 | K1: A9 | L1: A10 | M1: B1 | N1: B2 | O1: B3 | P1: B4 | Q1: B5 | R1: B6 | S1: B7 | T1: B8 | U1: B9 | V1: C1 | W1: C2 | X1: C3 | Y1: C4 | Z1: C5 | AA1: C6 | AB1: C7 | AC1: C8 | AD1: C9 | AE1: D1 | AF1: D2 | AG1: D3 | AH1: D4 | AI1: D5 | AJ1: D6 | AK1: D7 | AL1: D8 | AM1: D9 | AN1: D10 | AO1: E1 | AP1: E2 | AQ1: E3 | AR1: E4 | AS1: E5 | AT1: E6 | AU1: E7 | AV1: E8 | AW1: E9 | AX1: E10 | AY1: E11 | AZ1: F1 | BA1: F2 | BB1: F3 | BC1: F4 | BD1: F5 | BE1: F6 | BF1: F7 | BG1: F8 | BH1: F9 | BI1: F10 | BJ1: F11 | BK1: F12 | BL1: A nr. distincte | BM1: A nimerit | BN1: A pauză | BO1: B nr. distincte | BP1: B nimerit | BQ1: B pauză | BR1: C nr. distincte | BS1: C nimerit | BT1: C pauză | BU1: D nr. distincte | BV1: D nimerit | BW1: D pauză | BX1: E nr. distincte | BY1: E nimerit | BZ1: E pauză | CA1: F nr. distincte | CB1: F nimerit | CC1: F pauză
A2: 2026-05-05 07:00 | B2: 5 | C2: 10 | D2: 3 | E2: 10 | F2: 1 | G2: 3 | H2: 4 | I2: 9 | J2: 5 | K2: 12 | L2: 7 | M2: 8 | N2: 13 | O2: 15 | P2: 20 | Q2: 17 | R2: 10 | S2: 2 | T2: 5 | U2: 7 | V2: 10 | W2: 3 | X2: 1 | Y2: 4 | Z2: 9 | AA2: 5 | AB2: 12 | AC2: 7 | AD2: 8 | AE2: 10 | AF2: 3 | AG2: 1 | AH2: 4 | AI2: 9 | AJ2: 5 | AK2: 12 | AL2: 7 | AM2: 8 | AN2: 13 | AO2: 10 | AP2: 3 | AQ2: 1 | AR2: 4 | AS2: 9 | AT2: 5 | AU2: 12 | AV2: 7 | AW2: 8 | AX2: 13 | AY2: 15 | AZ2: 10 | BA2: 3 | BB2: 1 | BC2: 4 | BD2: 9 | BE2: 5 | BF2: 12 | BG2: 7 | BH2: 8 | BI2: 13 | BJ2: 15 | BK2: 20 | BL2: =(COUNTIF(C2:L2,1)>0)+(COUNTIF(C2:L2,2)>0)+(COUNTIF(C2:L2,3)>0)+(COUNTIF(C2:L2,4)>0)+(COUNTIF(C2:L2,5)>0)+(COUNTIF(C2:L2,6)>0)+(COUNTIF(C2:L2,7)>0)+(COUNTIF(C2:L2,8)>0)+(COUNTIF(C2:L2,9)>0)+(COUNTIF(C2:L2,10)>0)+(COUNTIF(C2:L2,11)>0)+(COUNTIF(C2:L2,12)>0)+(COUNTIF(C2:L2,13)>0)+(COUNTIF(C2:L2,14)>0)+(COUNTIF(C2:L2,15)>0)+(COUNTIF(C2:L2,16)>0)+(COUNTIF(C2:L2,17)>0)+(COUNTIF(C2:L2,18)>0)+(COUNTIF(C2:L2,19)>0)+(COUNTIF(C2:L2,20)>0) | BM2: =IF(ISNUMBER(MATCH($B2,C2:L2,0)),1,0) | BN2: =IF(BM2=1,0,0+1) | BO2: =(COUNTIF(M2:U2,1)>0)+(COUNTIF(M2:U2,2)>0)+(COUNTIF(M2:U2,3)>0)+(COUNTIF(M2:U2,4)>0)+(COUNTIF(M2:U2,5)>0)+(COUNTIF(M2:U2,6)>0)+(COUNTIF(M2:U2,7)>0)+(COUNTIF(M2:U2,8)>0)+(COUNTIF(M2:U2,9)>0)+(COUNTIF(M2:U2,10)>0)+(COUNTIF(M2:U2,11)>0)+(COUNTIF(M2:U2,12)>0)+(COUNTIF(M2:U2,13)>0)+(COUNTIF(M2:U2,14)>0)+(COUNTIF(M2:U2,15)>0)+(COUNTIF(M2:U2,16)>0)+(COUNTIF(M2:U2,17)>0)+(COUNTIF(M2:U2,18)>0)+(COUNTIF(M2:U2,19)>0)+(COUNTIF(M2:U2,20)>0) | BP2: =IF(ISNUMBER(MATCH($B2,M2:U2,0)),1,0) | BQ2: =IF(BP2=1,0,0+1) | BR2: =(COUNTIF(V2:AD2,1)>0)+(COUNTIF(V2:AD2,2)>0)+(COUNTIF(V2:AD2,3)>0)+(COUNTIF(V2:AD2,4)>0)+(COUNTIF(V2:AD2,5)>0)+(COUNTIF(V2:AD2,6)>0)+(COUNTIF(V2:AD2,7)>0)+(COUNTIF(V2:AD2,8)>0)+(COUNTIF(V2:AD2,9)>0)+(COUNTIF(V2:AD2,10)>0)+(COUNTIF(V2:AD2,11)>0)+(COUNTIF(V2:AD2,12)>0)+(COUNTIF(V2:AD2,13)>0)+(COUNTIF(V2:AD2,14)>0)+(COUNTIF(V2:AD2,15)>0)+(COUNTIF(V2:AD2,16)>0)+(COUNTIF(V2:AD2,17)>0)+(COUNTIF(V2:AD2,18)>0)+(COUNTIF(V2:AD2,19)>0)+(COUNTIF(V2:AD2,20)>0) | BS2: =IF(ISNUMBER(MATCH($B2,V2:AD2,0)),1,0) | BT2: =IF(BS2=1,0,0+1) | BU2: =(COUNTIF(AE2:AN2,1)>0)+(COUNTIF(AE2:AN2,2)>0)+(COUNTIF(AE2:AN2,3)>0)+(COUNTIF(AE2:AN2,4)>0)+(COUNTIF(AE2:AN2,5)>0)+(COUNTIF(AE2:AN2,6)>0)+(COUNTIF(AE2:AN2,7)>0)+(COUNTIF(AE2:AN2,8)>0)+(COUNTIF(AE2:AN2,9)>0)+(COUNTIF(AE2:AN2,10)>0)+(COUNTIF(AE2:AN2,11)>0)+(COUNTIF(AE2:AN2,12)>0)+(COUNTIF(AE2:AN2,13)>0)+(COUNTIF(AE2:AN2,14)>0)+(COUNTIF(AE2:AN2,15)>0)+(COUNTIF(AE2:AN2,16)>0)+(COUNTIF(AE2:AN2,17)>0)+(COUNTIF(AE2:AN2,18)>0)+(COUNTIF(AE2:AN2,19)>0)+(COUNTIF(AE2:AN2,20)>0) | BV2: =IF(ISNUMBER(MATCH($B2,AE2:AN2,0)),1,0) | BW2: =IF(BV2=1,0,0+1) | BX2: =(COUNTIF(AO2:AY2,1)>0)+(COUNTIF(AO2:AY2,2)>0)+(COUNTIF(AO2:AY2,3)>0)+(COUNTIF(AO2:AY2,4)>0)+(COUNTIF(AO2:AY2,5)>0)+(COUNTIF(AO2:AY2,6)>0)+(COUNTIF(AO2:AY2,7)>0)+(COUNTIF(AO2:AY2,8)>0)+(COUNTIF(AO2:AY2,9)>0)+(COUNTIF(AO2:AY2,10)>0)+(COUNTIF(AO2:AY2,11)>0)+(COUNTIF(AO2:AY2,12)>0)+(COUNTIF(AO2:AY2,13)>0)+(COUNTIF(AO2:AY2,14)>0)+(COUNTIF(AO2:AY2,15)>0)+(COUNTIF(AO2:AY2,16)>0)+(COUNTIF(AO2:AY2,17)>0)+(COUNTIF(AO2:AY2,18)>0)+(COUNTIF(AO2:AY2,19)>0)+(COUNTIF(AO2:AY2,20)>0) | BY2: =IF(ISNUMBER(MATCH($B2,AO2:AY2,0)),1,0) | BZ2: =IF(BY2=1,0,0+1) | CA2: =(COUNTIF(AZ2:BK2,1)>0)+(COUNTIF(AZ2:BK2,2)>0)+(COUNTIF(AZ2:BK2,3)>0)+(COUNTIF(AZ2:BK2,4)>0)+(COUNTIF(AZ2:BK2,5)>0)+(COUNTIF(AZ2:BK2,6)>0)+(COUNTIF(AZ2:BK2,7)>0)+(COUNTIF(AZ2:BK2,8)>0)+(COUNTIF(AZ2:BK2,9)>0)+(COUNTIF(AZ2:BK2,10)>0)+(COUNTIF(AZ2:BK2,11)>0)+(COUNTIF(AZ2:BK2,12)>0)+(COUNTIF(AZ2:BK2,13)>0)+(COUNTIF(AZ2:BK2,14)>0)+(COUNTIF(AZ2:BK2,15)>0)+(COUNTIF(AZ2:BK2,16)>0)+(COUNTIF(AZ2:BK2,17)>0)+(COUNTIF(AZ2:BK2,18)>0)+(COUNTIF(AZ2:BK2,19)>0)+(COUNTIF(AZ2:BK2,20)>0) | CB2: =IF(ISNUMBER(MATCH($B2,AZ2:BK2,0)),1,0) | CC2: =IF(CB2=1,0,0+1)
A3: 2026-05-05 08:00 | B3: 9 | C3: 9 | D3: 9 | E3: 1 | F3: 1 | G3: 7 | H3: 12 | I3: 8 | J3: 15 | K3: 16 | L3: 15 | M3: 19 | N3: 17 | O3: 18 | P3: 13 | Q3: 3 | R3: 11 | S3: 4 | T3: 5 | U3: 2 | V3: 9 | W3: 1 | X3: 7 | Y3: 12 | Z3: 8 | AA3: 15 | AB3: 16 | AC3: 19 | AD3: 17 | AE3: 9 | AF3: 1 | AG3: 7 | AH3: 12 | AI3: 8 | AJ3: 15 | AK3: 16 | AL3: 19 | AM3: 17 | AN3: 18 | AO3: 9 | AP3: 1 | AQ3: 7 | AR3: 12 | AS3: 8 | AT3: 15 | AU3: 16 | AV3: 19 | AW3: 17 | AX3: 18 | AY3: 13 | AZ3: 9 | BA3: 1 | BB3: 7 | BC3: 12 | BD3: 8 | BE3: 15 | BF3: 16 | BG3: 19 | BH3: 17 | BI3: 18 | BJ3: 13 | BK3: 3 | BL3: =(COUNTIF(C3:L3,1)>0)+(COUNTIF(C3:L3,2)>0)+(COUNTIF(C3:L3,3)>0)+(COUNTIF(C3:L3,4)>0)+(COUNTIF(C3:L3,5)>0)+(COUNTIF(C3:L3,6)>0)+(COUNTIF(C3:L3,7)>0)+(COUNTIF(C3:L3,8)>0)+(COUNTIF(C3:L3,9)>0)+(COUNTIF(C3:L3,10)>0)+(COUNTIF(C3:L3,11)>0)+(COUNTIF(C3:L3,12)>0)+(COUNTIF(C3:L3,13)>0)+(COUNTIF(C3:L3,14)>0)+(COUNTIF(C3:L3,15)>0)+(COUNTIF(C3:L3,16)>0)+(COUNTIF(C3:L3,17)>0)+(COUNTIF(C3:L3,18)>0)+(COUNTIF(C3:L3,19)>0)+(COUNTIF(C3:L3,20)>0) | BM3: =IF(ISNUMBER(MATCH($B3,C3:L3,0)),1,0) | BN3: =IF(BM3=1,0,BN2+1) | BO3: =(COUNTIF(M3:U3,1)>0)+(COUNTIF(M3:U3,2)>0)+(COUNTIF(M3:U3,3)>0)+(COUNTIF(M3:U3,4)>0)+(COUNTIF(M3:U3,5)>0)+(COUNTIF(M3:U3,6)>0)+(COUNTIF(M3:U3,7)>0)+(COUNTIF(M3:U3,8)>0)+(COUNTIF(M3:U3,9)>0)+(COUNTIF(M3:U3,10)>0)+(COUNTIF(M3:U3,11)>0)+(COUNTIF(M3:U3,12)>0)+(COUNTIF(M3:U3,13)>0)+(COUNTIF(M3:U3,14)>0)+(COUNTIF(M3:U3,15)>0)+(COUNTIF(M3:U3,16)>0)+(COUNTIF(M3:U3,17)>0)+(COUNTIF(M3:U3,18)>0)+(COUNTIF(M3:U3,19)>0)+(COUNTIF(M3:U3,20)>0) | BP3: =IF(ISNUMBER(MATCH($B3,M3:U3,0)),1,0) | BQ3: =IF(BP3=1,0,BQ2+1) | BR3: =(COUNTIF(V3:AD3,1)>0)+(COUNTIF(V3:AD3,2)>0)+(COUNTIF(V3:AD3,3)>0)+(COUNTIF(V3:AD3,4)>0)+(COUNTIF(V3:AD3,5)>0)+(COUNTIF(V3:AD3,6)>0)+(COUNTIF(V3:AD3,7)>0)+(COUNTIF(V3:AD3,8)>0)+(COUNTIF(V3:AD3,9)>0)+(COUNTIF(V3:AD3,10)>0)+(COUNTIF(V3:AD3,11)>0)+(COUNTIF(V3:AD3,12)>0)+(COUNTIF(V3:AD3,13)>0)+(COUNTIF(V3:AD3,14)>0)+(COUNTIF(V3:AD3,15)>0)+(COUNTIF(V3:AD3,16)>0)+(COUNTIF(V3:AD3,17)>0)+(COUNTIF(V3:AD3,18)>0)+(COUNTIF(V3:AD3,19)>0)+(COUNTIF(V3:AD3,20)>0) | BS3: =IF(ISNUMBER(MATCH($B3,V3:AD3,0)),1,0) | BT3: =IF(BS3=1,0,BT2+1) | BU3: =(COUNTIF(AE3:AN3,1)>0)+(COUNTIF(AE3:AN3,2)>0)+(COUNTIF(AE3:AN3,3)>0)+(COUNTIF(AE3:AN3,4)>0)+(COUNTIF(AE3:AN3,5)>0)+(COUNTIF(AE3:AN3,6)>0)+(COUNTIF(AE3:AN3,7)>0)+(COUNTIF(AE3:AN3,8)>0)+(COUNTIF(AE3:AN3,9)>0)+(COUNTIF(AE3:AN3,10)>0)+(COUNTIF(AE3:AN3,11)>0)+(COUNTIF(AE3:AN3,12)>0)+(COUNTIF(AE3:AN3,13)>0)+(COUNTIF(AE3:AN3,14)>0)+(COUNTIF(AE3:AN3,15)>0)+(COUNTIF(AE3:AN3,16)>0)+(COUNTIF(AE3:AN3,17)>0)+(COUNTIF(AE3:AN3,18)>0)+(COUNTIF(AE3:AN3,19)>0)+(COUNTIF(AE3:AN3,20)>0) | BV3: =IF(ISNUMBER(MATCH($B3,AE3:AN3,0)),1,0) | BW3: =IF(BV3=1,0,BW2+1) | BX3: =(COUNTIF(AO3:AY3,1)>0)+(COUNTIF(AO3:AY3,2)>0)+(COUNTIF(AO3:AY3,3)>0)+(COUNTIF(AO3:AY3,4)>0)+(COUNTIF(AO3:AY3,5)>0)+(COUNTIF(AO3:AY3,6)>0)+(COUNTIF(AO3:AY3,7)>0)+(COUNTIF(AO3:AY3,8)>0)+(COUNTIF(AO3:AY3,9)>0)+(COUNTIF(AO3:AY3,10)>0)+(COUNTIF(AO3:AY3,11)>0)+(COUNTIF(AO3:AY3,12)>0)+(COUNTIF(AO3:AY3,13)>0)+(COUNTIF(AO3:AY3,14)>0)+(COUNTIF(AO3:AY3,15)>0)+(COUNTIF(AO3:AY3,16)>0)+(COUNTIF(AO3:AY3,17)>0)+(COUNTIF(AO3:AY3,18)>0)+(COUNTIF(AO3:AY3,19)>0)+(COUNTIF(AO3:AY3,20)>0) | BY3: =IF(ISNUMBER(MATCH($B3,AO3:AY3,0)),1,0) | BZ3: =IF(BY3=1,0,BZ2+1) | CA3: =(COUNTIF(AZ3:BK3,1)>0)+(COUNTIF(AZ3:BK3,2)>0)+(COUNTIF(AZ3:BK3,3)>0)+(COUNTIF(AZ3:BK3,4)>0)+(COUNTIF(AZ3:BK3,5)>0)+(COUNTIF(AZ3:BK3,6)>0)+(COUNTIF(AZ3:BK3,7)>0)+(COUNTIF(AZ3:BK3,8)>0)+(COUNTIF(AZ3:BK3,9)>0)+(COUNTIF(AZ3:BK3,10)>0)+(COUNTIF(AZ3:BK3,11)>0)+(COUNTIF(AZ3:BK3,12)>0)+(COUNTIF(AZ3:BK3,13)>0)+(COUNTIF(AZ3:BK3,14)>0)+(COUNTIF(AZ3:BK3,15)>0)+(COUNTIF(AZ3:BK3,16)>0)+(COUNTIF(AZ3:BK3,17)>0)+(COUNTIF(AZ3:BK3,18)>0)+(COUNTIF(AZ3:BK3,19)>0)+(COUNTIF(AZ3:BK3,20)>0) | CB3: =IF(ISNUMBER(MATCH($B3,AZ3:BK3,0)),1,0) | CC3: =IF(CB3=1,0,CC2+1)
A4: 2026-05-05 09:00 | B4: 5 | C4: 4 | D4: 17 | E4: 16 | F4: 5 | G4: 17 | H4: 19 | I4: 10 | J4: 7 | K4: 5 | L4: 1 | M4: 4 | N4: 8 | O4: 20 | P4: 5 | Q4: 11 | R4: 14 | S4: 7 | T4: 16 | U4: 3 | V4: 4 | W4: 17 | X4: 16 | Y4: 5 | Z4: 19 | AA4: 10 | AB4: 7 | AC4: 1 | AD4: 8 | AE4: 4 | AF4: 17 | AG4: 16 | AH4: 5 | AI4: 19 | AJ4: 10 | AK4: 7 | AL4: 1 | AM4: 8 | AN4: 20 | AO4: 4 | AP4: 17 | AQ4: 16 | AR4: 5 | AS4: 19 | AT4: 10 | AU4: 7 | AV4: 1 | AW4: 8 | AX4: 20 | AY4: 11 | AZ4: 4 | BA4: 17 | BB4: 16 | BC4: 5 | BD4: 19 | BE4: 10 | BF4: 7 | BG4: 1 | BH4: 8 | BI4: 20 | BJ4: 11 | BK4: 14 | BL4: =(COUNTIF(C4:L4,1)>0)+(COUNTIF(C4:L4,2)>0)+(COUNTIF(C4:L4,3)>0)+(COUNTIF(C4:L4,4)>0)+(COUNTIF(C4:L4,5)>0)+(COUNTIF(C4:L4,6)>0)+(COUNTIF(C4:L4,7)>0)+(COUNTIF(C4:L4,8)>0)+(COUNTIF(C4:L4,9)>0)+(COUNTIF(C4:L4,10)>0)+(COUNTIF(C4:L4,11)>0)+(COUNTIF(C4:L4,12)>0)+(COUNTIF(C4:L4,13)>0)+(COUNTIF(C4:L4,14)>0)+(COUNTIF(C4:L4,15)>0)+(COUNTIF(C4:L4,16)>0)+(COUNTIF(C4:L4,17)>0)+(COUNTIF(C4:L4,18)>0)+(COUNTIF(C4:L4,19)>0)+(COUNTIF(C4:L4,20)>0) | BM4: =IF(ISNUMBER(MATCH($B4,C4:L4,0)),1,0) | BN4: =IF(BM4=1,0,BN3+1) | BO4: =(COUNTIF(M4:U4,1)>0)+(COUNTIF(M4:U4,2)>0)+(COUNTIF(M4:U4,3)>0)+(COUNTIF(M4:U4,4)>0)+(COUNTIF(M4:U4,5)>0)+(COUNTIF(M4:U4,6)>0)+(COUNTIF(M4:U4,7)>0)+(COUNTIF(M4:U4,8)>0)+(COUNTIF(M4:U4,9)>0)+(COUNTIF(M4:U4,10)>0)+(COUNTIF(M4:U4,11)>0)+(COUNTIF(M4:U4,12)>0)+(COUNTIF(M4:U4,13)>0)+(COUNTIF(M4:U4,14)>0)+(COUNTIF(M4:U4,15)>0)+(COUNTIF(M4:U4,16)>0)+(COUNTIF(M4:U4,17)>0)+(COUNTIF(M4:U4,18)>0)+(COUNTIF(M4:U4,19)>0)+(COUNTIF(M4:U4,20)>0) | BP4: =IF(ISNUMBER(MATCH($B4,M4:U4,0)),1,0) | BQ4: =IF(BP4=1,0,BQ3+1) | BR4: =(COUNTIF(V4:AD4,1)>0)+(COUNTIF(V4:AD4,2)>0)+(COUNTIF(V4:AD4,3)>0)+(COUNTIF(V4:AD4,4)>0)+(COUNTIF(V4:AD4,5)>0)+(COUNTIF(V4:AD4,6)>0)+(COUNTIF(V4:AD4,7)>0)+(COUNTIF(V4:AD4,8)>0)+(COUNTIF(V4:AD4,9)>0)+(COUNTIF(V4:AD4,10)>0)+(COUNTIF(V4:AD4,11)>0)+(COUNTIF(V4:AD4,12)>0)+(COUNTIF(V4:AD4,13)>0)+(COUNTIF(V4:AD4,14)>0)+(COUNTIF(V4:AD4,15)>0)+(COUNTIF(V4:AD4,16)>0)+(COUNTIF(V4:AD4,17)>0)+(COUNTIF(V4:AD4,18)>0)+(COUNTIF(V4:AD4,19)>0)+(COUNTIF(V4:AD4,20)>0) | BS4: =IF(ISNUMBER(MATCH($B4,V4:AD4,0)),1,0) | BT4: =IF(BS4=1,0,BT3+1) | BU4: =(COUNTIF(AE4:AN4,1)>0)+(COUNTIF(AE4:AN4,2)>0)+(COUNTIF(AE4:AN4,3)>0)+(COUNTIF(AE4:AN4,4)>0)+(COUNTIF(AE4:AN4,5)>0)+(COUNTIF(AE4:AN4,6)>0)+(COUNTIF(AE4:AN4,7)>0)+(COUNTIF(AE4:AN4,8)>0)+(COUNTIF(AE4:AN4,9)>0)+(COUNTIF(AE4:AN4,10)>0)+(COUNTIF(AE4:AN4,11)>0)+(COUNTIF(AE4:AN4,12)>0)+(COUNTIF(AE4:AN4,13)>0)+(COUNTIF(AE4:AN4,14)>0)+(COUNTIF(AE4:AN4,15)>0)+(COUNTIF(AE4:AN4,16)>0)+(COUNTIF(AE4:AN4,17)>0)+(COUNTIF(AE4:AN4,18)>0)+(COUNTIF(AE4:AN4,19)>0)+(COUNTIF(AE4:AN4,20)>0) | BV4: =IF(ISNUMBER(MATCH($B4,AE4:AN4,0)),1,0) | BW4: =IF(BV4=1,0,BW3+1) | BX4: =(COUNTIF(AO4:AY4,1)>0)+(COUNTIF(AO4:AY4,2)>0)+(COUNTIF(AO4:AY4,3)>0)+(COUNTIF(AO4:AY4,4)>0)+(COUNTIF(AO4:AY4,5)>0)+(COUNTIF(AO4:AY4,6)>0)+(COUNTIF(AO4:AY4,7)>0)+(COUNTIF(AO4:AY4,8)>0)+(COUNTIF(AO4:AY4,9)>0)+(COUNTIF(AO4:AY4,10)>0)+(COUNTIF(AO4:AY4,11)>0)+(COUNTIF(AO4:AY4,12)>0)+(COUNTIF(AO4:AY4,13)>0)+(COUNTIF(AO4:AY4,14)>0)+(COUNTIF(AO4:AY4,15)>0)+(COUNTIF(AO4:AY4,16)>0)+(COUNTIF(AO4:AY4,17)>0)+(COUNTIF(AO4:AY4,18)>0)+(COUNTIF(AO4:AY4,19)>0)+(COUNTIF(AO4:AY4,20)>0) | BY4: =IF(ISNUMBER(MATCH($B4,AO4:AY4,0)),1,0) | BZ4: =IF(BY4=1,0,BZ3+1) | CA4: =(COUNTIF(AZ4:BK4,1)>0)+(COUNTIF(AZ4:BK4,2)>0)+(COUNTIF(AZ4:BK4,3)>0)+(COUNTIF(AZ4:BK4,4)>0)+(COUNTIF(AZ4:BK4,5)>0)+(COUNTIF(AZ4:BK4,6)>0)+(COUNTIF(AZ4:BK4,7)>0)+(COUNTIF(AZ4:BK4,8)>0)+(COUNTIF(AZ4:BK4,9)>0)+(COUNTIF(AZ4:BK4,10)>0)+(COUNTIF(AZ4:BK4,11)>0)+(COUNTIF(AZ4:BK4,12)>0)+(COUNTIF(AZ4:BK4,13)>0)+(COUNTIF(AZ4:BK4,14)>0)+(COUNTIF(AZ4:BK4,15)>0)+(COUNTIF(AZ4:BK4,16)>0)+(COUNTIF(AZ4:BK4,17)>0)+(COUNTIF(AZ4:BK4,18)>0)+(COUNTIF(AZ4:BK4,19)>0)+(COUNTIF(AZ4:BK4,20)>0) | CB4: =IF(ISNUMBER(MATCH($B4,AZ4:BK4,0)),1,0) | CC4: =IF(CB4=1,0,CC3+1)
A5: 2026-05-05 10:00 | B5: 17 | C5: 19 | D5: 19 | E5: 11 | F5: 11 | G5: 15 | H5: 13 | I5: 15 | J5: 14 | K5: 15 | L5: 15 | M5: 17 | N5: 14 | O5: 15 | P5: 19 | Q5: 13 | R5: 2 | S5: 20 | T5: 11 | U5: 5 | V5: 19 | W5: 11 | X5: 15 | Y5: 13 | Z5: 14 | AA5: 17 | AB5: 2 | AC5: 20 | AD5: 5 | AE5: 19 | AF5: 11 | AG5: 15 | AH5: 13 | AI5: 14 | AJ5: 17 | AK5: 2 | AL5: 20 | AM5: 5 | AO5: 19 | AP5: 11 | AQ5: 15 | AR5: 13 | AS5: 14 | AT5: 17 | AU5: 2 | AV5: 20 | AW5: 5 | AZ5: 19 | BA5: 11 | BB5: 15 | BC5: 13 | BD5: 14 | BE5: 17 | BF5: 2 | BG5: 20 | BH5: 5 | BL5: =(COUNTIF(C5:L5,1)>0)+(COUNTIF(C5:L5,2)>0)+(COUNTIF(C5:L5,3)>0)+(COUNTIF(C5:L5,4)>0)+(COUNTIF(C5:L5,5)>0)+(COUNTIF(C5:L5,6)>0)+(COUNTIF(C5:L5,7)>0)+(COUNTIF(C5:L5,8)>0)+(COUNTIF(C5:L5,9)>0)+(COUNTIF(C5:L5,10)>0)+(COUNTIF(C5:L5,11)>0)+(COUNTIF(C5:L5,12)>0)+(COUNTIF(C5:L5,13)>0)+(COUNTIF(C5:L5,14)>0)+(COUNTIF(C5:L5,15)>0)+(COUNTIF(C5:L5,16)>0)+(COUNTIF(C5:L5,17)>0)+(COUNTIF(C5:L5,18)>0)+(COUNTIF(C5:L5,19)>0)+(COUNTIF(C5:L5,20)>0) | BM5: =IF(ISNUMBER(MATCH($B5,C5:L5,0)),1,0) | BN5: =IF(BM5=1,0,BN4+1) | BO5: =(COUNTIF(M5:U5,1)>0)+(COUNTIF(M5:U5,2)>0)+(COUNTIF(M5:U5,3)>0)+(COUNTIF(M5:U5,4)>0)+(COUNTIF(M5:U5,5)>0)+(COUNTIF(M5:U5,6)>0)+(COUNTIF(M5:U5,7)>0)+(COUNTIF(M5:U5,8)>0)+(COUNTIF(M5:U5,9)>0)+(COUNTIF(M5:U5,10)>0)+(COUNTIF(M5:U5,11)>0)+(COUNTIF(M5:U5,12)>0)+(COUNTIF(M5:U5,13)>0)+(COUNTIF(M5:U5,14)>0)+(COUNTIF(M5:U5,15)>0)+(COUNTIF(M5:U5,16)>0)+(COUNTIF(M5:U5,17)>0)+(COUNTIF(M5:U5,18)>0)+(COUNTIF(M5:U5,19)>0)+(COUNTIF(M5:U5,20)>0) | BP5: =IF(ISNUMBER(MATCH($B5,M5:U5,0)),1,0) | BQ5: =IF(BP5=1,0,BQ4+1) | BR5: =(COUNTIF(V5:AD5,1)>0)+(COUNTIF(V5:AD5,2)>0)+(COUNTIF(V5:AD5,3)>0)+(COUNTIF(V5:AD5,4)>0)+(COUNTIF(V5:AD5,5)>0)+(COUNTIF(V5:AD5,6)>0)+(COUNTIF(V5:AD5,7)>0)+(COUNTIF(V5:AD5,8)>0)+(COUNTIF(V5:AD5,9)>0)+(COUNTIF(V5:AD5,10)>0)+(COUNTIF(V5:AD5,11)>0)+(COUNTIF(V5:AD5,12)>0)+(COUNTIF(V5:AD5,13)>0)+(COUNTIF(V5:AD5,14)>0)+(COUNTIF(V5:AD5,15)>0)+(COUNTIF(V5:AD5,16)>0)+(COUNTIF(V5:AD5,17)>0)+(COUNTIF(V5:AD5,18)>0)+(COUNTIF(V5:AD5,19)>0)+(COUNTIF(V5:AD5,20)>0) | BS5: =IF(ISNUMBER(MATCH($B5,V5:AD5,0)),1,0) | BT5: =IF(BS5=1,0,BT4+1) | BU5: =(COUNTIF(AE5:AN5,1)>0)+(COUNTIF(AE5:AN5,2)>0)+(COUNTIF(AE5:AN5,3)>0)+(COUNTIF(AE5:AN5,4)>0)+(COUNTIF(AE5:AN5,5)>0)+(COUNTIF(AE5:AN5,6)>0)+(COUNTIF(AE5:AN5,7)>0)+(COUNTIF(AE5:AN5,8)>0)+(COUNTIF(AE5:AN5,9)>0)+(COUNTIF(AE5:AN5,10)>0)+(COUNTIF(AE5:AN5,11)>0)+(COUNTIF(AE5:AN5,12)>0)+(COUNTIF(AE5:AN5,13)>0)+(COUNTIF(AE5:AN5,14)>0)+(COUNTIF(AE5:AN5,15)>0)+(COUNTIF(AE5:AN5,16)>0)+(COUNTIF(AE5:AN5,17)>0)+(COUNTIF(AE5:AN5,18)>0)+(COUNTIF(AE5:AN5,19)>0)+(COUNTIF(AE5:AN5,20)>0) | BV5: =IF(ISNUMBER(MATCH($B5,AE5:AN5,0)),1,0) | BW5: =IF(BV5=1,0,BW4+1) | BX5: =(COUNTIF(AO5:AY5,1)>0)+(COUNTIF(AO5:AY5,2)>0)+(COUNTIF(AO5:AY5,3)>0)+(COUNTIF(AO5:AY5,4)>0)+(COUNTIF(AO5:AY5,5)>0)+(COUNTIF(AO5:AY5,6)>0)+(COUNTIF(AO5:AY5,7)>0)+(COUNTIF(AO5:AY5,8)>0)+(COUNTIF(AO5:AY5,9)>0)+(COUNTIF(AO5:AY5,10)>0)+(COUNTIF(AO5:AY5,11)>0)+(COUNTIF(AO5:AY5,12)>0)+(COUNTIF(AO5:AY5,13)>0)+(COUNTIF(AO5:AY5,14)>0)+(COUNTIF(AO5:AY5,15)>0)+(COUNTIF(AO5:AY5,16)>0)+(COUNTIF(AO5:AY5,17)>0)+(COUNTIF(AO5:AY5,18)>0)+(COUNTIF(AO5:AY5,19)>0)+(COUNTIF(AO5:AY5,20)>0) | BY5: =IF(ISNUMBER(MATCH($B5,AO5:AY5,0)),1,0) | BZ5: =IF(BY5=1,0,BZ4+1) | CA5: =(COUNTIF(AZ5:BK5,1)>0)+(COUNTIF(AZ5:BK5,2)>0)+(COUNTIF(AZ5:BK5,3)>0)+(COUNTIF(AZ5:BK5,4)>0)+(COUNTIF(AZ5:BK5,5)>0)+(COUNTIF(AZ5:BK5,6)>0)+(COUNTIF(AZ5:BK5,7)>0)+(COUNTIF(AZ5:BK5,8)>0)+(COUNTIF(AZ5:BK5,9)>0)+(COUNTIF(AZ5:BK5,10)>0)+(COUNTIF(AZ5:BK5,11)>0)+(COUNTIF(AZ5:BK5,12)>0)+(COUNTIF(AZ5:BK5,13)>0)+(COUNTIF(AZ5:BK5,14)>0)+(COUNTIF(AZ5:BK5,15)>0)+(COUNTIF(AZ5:BK5,16)>0)+(COUNTIF(AZ5:BK5,17)>0)+(COUNTIF(AZ5:BK5,18)>0)+(COUNTIF(AZ5:BK5,19)>0)+(COUNTIF(AZ5:BK5,20)>0) | CB5: =IF(ISNUMBER(MATCH($B5,AZ5:BK5,0)),1,0) | CC5: =IF(CB5=1,0,CC4+1)
A6: 2026-05-05 11:00 | B6: 10 | C6: 15 | D6: 8 | E6: 9 | F6: 6 | G6: 10 | H6: 19 | I6: 20 | J6: 11 | K6: 11 | L6: 3 | M6: 5 | N6: 20 | O6: 19 | P6: 8 | Q6: 2 | R6: 13 | S6: 11 | T6: 15 | U6: 6 | V6: 15 | W6: 8 | X6: 9 | Y6: 6 | Z6: 10 | AA6: 19 | AB6: 20 | AC6: 11 | AD6: 3 | AE6: 15 | AF6: 8 | AG6: 9 | AH6: 6 | AI6: 10 | AJ6: 19 | AK6: 20 | AL6: 11 | AM6: 3 | AN6: 5 | AO6: 15 | AP6: 8 | AQ6: 9 | AR6: 6 | AS6: 10 | AT6: 19 | AU6: 20 | AV6: 11 | AW6: 3 | AX6: 5 | AY6: 2 | AZ6: 15 | BA6: 8 | BB6: 9 | BC6: 6 | BD6: 10 | BE6: 19 | BF6: 20 | BG6: 11 | BH6: 3 | BI6: 5 | BJ6: 2 | BK6: 13 | BL6: =(COUNTIF(C6:L6,1)>0)+(COUNTIF(C6:L6,2)>0)+(COUNTIF(C6:L6,3)>0)+(COUNTIF(C6:L6,4)>0)+(COUNTIF(C6:L6,5)>0)+(COUNTIF(C6:L6,6)>0)+(COUNTIF(C6:L6,7)>0)+(COUNTIF(C6:L6,8)>0)+(COUNTIF(C6:L6,9)>0)+(COUNTIF(C6:L6,10)>0)+(COUNTIF(C6:L6,11)>0)+(COUNTIF(C6:L6,12)>0)+(COUNTIF(C6:L6,13)>0)+(COUNTIF(C6:L6,14)>0)+(COUNTIF(C6:L6,15)>0)+(COUNTIF(C6:L6,16)>0)+(COUNTIF(C6:L6,17)>0)+(COUNTIF(C6:L6,18)>0)+(COUNTIF(C6:L6,19)>0)+(COUNTIF(C6:L6,20)>0) | BM6: =IF(ISNUMBER(MATCH($B6,C6:L6,0)),1,0) | BN6: =IF(BM6=1,0,BN5+1) | BO6: =(COUNTIF(M6:U6,1)>0)+(COUNTIF(M6:U6,2)>0)+(COUNTIF(M6:U6,3)>0)+(COUNTIF(M6:U6,4)>0)+(COUNTIF(M6:U6,5)>0)+(COUNTIF(M6:U6,6)>0)+(COUNTIF(M6:U6,7)>0)+(COUNTIF(M6:U6,8)>0)+(COUNTIF(M6:U6,9)>0)+(COUNTIF(M6:U6,10)>0)+(COUNTIF(M6:U6,11)>0)+(COUNTIF(M6:U6,12)>0)+(COUNTIF(M6:U6,13)>0)+(COUNTIF(M6:U6,14)>0)+(COUNTIF(M6:U6,15)>0)+(COUNTIF(M6:U6,16)>0)+(COUNTIF(M6:U6,17)>0)+(COUNTIF(M6:U6,18)>0)+(COUNTIF(M6:U6,19)>0)+(COUNTIF(M6:U6,20)>0) | BP6: =IF(ISNUMBER(MATCH($B6,M6:U6,0)),1,0) | BQ6: =IF(BP6=1,0,BQ5+1) | BR6: =(COUNTIF(V6:AD6,1)>0)+(COUNTIF(V6:AD6,2)>0)+(COUNTIF(V6:AD6,3)>0)+(COUNTIF(V6:AD6,4)>0)+(COUNTIF(V6:AD6,5)>0)+(COUNTIF(V6:AD6,6)>0)+(COUNTIF(V6:AD6,7)>0)+(COUNTIF(V6:AD6,8)>0)+(COUNTIF(V6:AD6,9)>0)+(COUNTIF(V6:AD6,10)>0)+(COUNTIF(V6:AD6,11)>0)+(COUNTIF(V6:AD6,12)>0)+(COUNTIF(V6:AD6,13)>0)+(COUNTIF(V6:AD6,14)>0)+(COUNTIF(V6:AD6,15)>0)+(COUNTIF(V6:AD6,16)>0)+(COUNTIF(V6:AD6,17)>0)+(COUNTIF(V6:AD6,18)>0)+(COUNTIF(V6:AD6,19)>0)+(COUNTIF(V6:AD6,20)>0) | BS6: =IF(ISNUMBER(MATCH($B6,V6:AD6,0)),1,0) | BT6: =IF(BS6=1,0,BT5+1) | BU6: =(COUNTIF(AE6:AN6,1)>0)+(COUNTIF(AE6:AN6,2)>0)+(COUNTIF(AE6:AN6,3)>0)+(COUNTIF(AE6:AN6,4)>0)+(COUNTIF(AE6:AN6,5)>0)+(COUNTIF(AE6:AN6,6)>0)+(COUNTIF(AE6:AN6,7)>0)+(COUNTIF(AE6:AN6,8)>0)+(COUNTIF(AE6:AN6,9)>0)+(COUNTIF(AE6:AN6,10)>0)+(COUNTIF(AE6:AN6,11)>0)+(COUNTIF(AE6:AN6,12)>0)+(COUNTIF(AE6:AN6,13)>0)+(COUNTIF(AE6:AN6,14)>0)+(COUNTIF(AE6:AN6,15)>0)+(COUNTIF(AE6:AN6,16)>0)+(COUNTIF(AE6:AN6,17)>0)+(COUNTIF(AE6:AN6,18)>0)+(COUNTIF(AE6:AN6,19)>0)+(COUNTIF(AE6:AN6,20)>0) | BV6: =IF(ISNUMBER(MATCH($B6,AE6:AN6,0)),1,0) | BW6: =IF(BV6=1,0,BW5+1) | BX6: =(COUNTIF(AO6:AY6,1)>0)+(COUNTIF(AO6:AY6,2)>0)+(COUNTIF(AO6:AY6,3)>0)+(COUNTIF(AO6:AY6,4)>0)+(COUNTIF(AO6:AY6,5)>0)+(COUNTIF(AO6:AY6,6)>0)+(COUNTIF(AO6:AY6,7)>0)+(COUNTIF(AO6:AY6,8)>0)+(COUNTIF(AO6:AY6,9)>0)+(COUNTIF(AO6:AY6,10)>0)+(COUNTIF(AO6:AY6,11)>0)+(COUNTIF(AO6:AY6,12)>0)+(COUNTIF(AO6:AY6,13)>0)+(COUNTIF(AO6:AY6,14)>0)+(COUNTIF(AO6:AY6,15)>0)+(COUNTIF(AO6:AY6,16)>0)+(COUNTIF(AO6:AY6,17)>0)+(COUNTIF(AO6:AY6,18)>0)+(COUNTIF(AO6:AY6,19)>0)+(COUNTIF(AO6:AY6,20)>0) | BY6: =IF(ISNUMBER(MATCH($B6,AO6:AY6,0)),1,0) | BZ6: =IF(BY6=1,0,BZ5+1) | CA6: =(COUNTIF(AZ6:BK6,1)>0)+(COUNTIF(AZ6:BK6,2)>0)+(COUNTIF(AZ6:BK6,3)>0)+(COUNTIF(AZ6:BK6,4)>0)+(COUNTIF(AZ6:BK6,5)>0)+(COUNTIF(AZ6:BK6,6)>0)+(COUNTIF(AZ6:BK6,7)>0)+(COUNTIF(AZ6:BK6,8)>0)+(COUNTIF(AZ6:BK6,9)>0)+(COUNTIF(AZ6:BK6,10)>0)+(COUNTIF(AZ6:BK6,11)>0)+(COUNTIF(AZ6:BK6,12)>0)+(COUNTIF(AZ6:BK6,13)>0)+(COUNTIF(AZ6:BK6,14)>0)+(COUNTIF(AZ6:BK6,15)>0)+(COUNTIF(AZ6:BK6,16)>0)+(COUNTIF(AZ6:BK6,17)>0)+(COUNTIF(AZ6:BK6,18)>0)+(COUNTIF(AZ6:BK6,19)>0)+(COUNTIF(AZ6:BK6,20)>0) | CB6: =IF(ISNUMBER(MATCH($B6,AZ6:BK6,0)),1,0) | CC6: =IF(CB6=1,0,CC5+1)
A7: 2026-05-05 12:00 | B7: 2 | C7: 7 | D7: 20 | E7: 10 | F7: 10 | G7: 12 | H7: 3 | I7: 1 | J7: 15 | K7: 16 | L7: 13 | M7: 2 | N7: 17 | O7: 7 | P7: 13 | Q7: 14 | R7: 8 | S7: 5 | T7: 20 | U7: 6 | V7: 7 | W7: 20 | X7: 10 | Y7: 12 | Z7: 3 | AA7: 1 | AB7: 15 | AC7: 16 | AD7: 13 | AE7: 7 | AF7: 20 | AG7: 10 | AH7: 12 | AI7: 3 | AJ7: 1 | AK7: 15 | AL7: 16 | AM7: 13 | AN7: 2 | AO7: 7 | AP7: 20 | AQ7: 10 | AR7: 12 | AS7: 3 | AT7: 1 | AU7: 15 | AV7: 16 | AW7: 13 | AX7: 2 | AY7: 17 | AZ7: 7 | BA7: 20 | BB7: 10 | BC7: 12 | BD7: 3 | BE7: 1 | BF7: 15 | BG7: 16 | BH7: 13 | BI7: 2 | BJ7: 17 | BK7: 14 | BL7: =(COUNTIF(C7:L7,1)>0)+(COUNTIF(C7:L7,2)>0)+(COUNTIF(C7:L7,3)>0)+(COUNTIF(C7:L7,4)>0)+(COUNTIF(C7:L7,5)>0)+(COUNTIF(C7:L7,6)>0)+(COUNTIF(C7:L7,7)>0)+(COUNTIF(C7:L7,8)>0)+(COUNTIF(C7:L7,9)>0)+(COUNTIF(C7:L7,10)>0)+(COUNTIF(C7:L7,11)>0)+(COUNTIF(C7:L7,12)>0)+(COUNTIF(C7:L7,13)>0)+(COUNTIF(C7:L7,14)>0)+(COUNTIF(C7:L7,15)>0)+(COUNTIF(C7:L7,16)>0)+(COUNTIF(C7:L7,17)>0)+(COUNTIF(C7:L7,18)>0)+(COUNTIF(C7:L7,19)>0)+(COUNTIF(C7:L7,20)>0) | BM7: =IF(ISNUMBER(MATCH($B7,C7:L7,0)),1,0) | BN7: =IF(BM7=1,0,BN6+1) | BO7: =(COUNTIF(M7:U7,1)>0)+(COUNTIF(M7:U7,2)>0)+(COUNTIF(M7:U7,3)>0)+(COUNTIF(M7:U7,4)>0)+(COUNTIF(M7:U7,5)>0)+(COUNTIF(M7:U7,6)>0)+(COUNTIF(M7:U7,7)>0)+(COUNTIF(M7:U7,8)>0)+(COUNTIF(M7:U7,9)>0)+(COUNTIF(M7:U7,10)>0)+(COUNTIF(M7:U7,11)>0)+(COUNTIF(M7:U7,12)>0)+(COUNTIF(M7:U7,13)>0)+(COUNTIF(M7:U7,14)>0)+(COUNTIF(M7:U7,15)>0)+(COUNTIF(M7:U7,16)>0)+(COUNTIF(M7:U7,17)>0)+(COUNTIF(M7:U7,18)>0)+(COUNTIF(M7:U7,19)>0)+(COUNTIF(M7:U7,20)>0) | BP7: =IF(ISNUMBER(MATCH($B7,M7:U7,0)),1,0) | BQ7: =IF(BP7=1,0,BQ6+1) | BR7: =(COUNTIF(V7:AD7,1)>0)+(COUNTIF(V7:AD7,2)>0)+(COUNTIF(V7:AD7,3)>0)+(COUNTIF(V7:AD7,4)>0)+(COUNTIF(V7:AD7,5)>0)+(COUNTIF(V7:AD7,6)>0)+(COUNTIF(V7:AD7,7)>0)+(COUNTIF(V7:AD7,8)>0)+(COUNTIF(V7:AD7,9)>0)+(COUNTIF(V7:AD7,10)>0)+(COUNTIF(V7:AD7,11)>0)+(COUNTIF(V7:AD7,12)>0)+(COUNTIF(V7:AD7,13)>0)+(COUNTIF(V7:AD7,14)>0)+(COUNTIF(V7:AD7,15)>0)+(COUNTIF(V7:AD7,16)>0)+(COUNTIF(V7:AD7,17)>0)+(COUNTIF(V7:AD7,18)>0)+(COUNTIF(V7:AD7,19)>0)+(COUNTIF(V7:AD7,20)>0) | BS7: =IF(ISNUMBER(MATCH($B7,V7:AD7,0)),1,0) | BT7: =IF(BS7=1,0,BT6+1) | BU7: =(COUNTIF(AE7:AN7,1)>0)+(COUNTIF(AE7:AN7,2)>0)+(COUNTIF(AE7:AN7,3)>0)+(COUNTIF(AE7:AN7,4)>0)+(COUNTIF(AE7:AN7,5)>0)+(COUNTIF(AE7:AN7,6)>0)+(COUNTIF(AE7:AN7,7)>0)+(COUNTIF(AE7:AN7,8)>0)+(COUNTIF(AE7:AN7,9)>0)+(COUNTIF(AE7:AN7,10)>0)+(COUNTIF(AE7:AN7,11)>0)+(COUNTIF(AE7:AN7,12)>0)+(COUNTIF(AE7:AN7,13)>0)+(COUNTIF(AE7:AN7,14)>0)+(COUNTIF(AE7:AN7,15)>0)+(COUNTIF(AE7:AN7,16)>0)+(COUNTIF(AE7:AN7,17)>0)+(COUNTIF(AE7:AN7,18)>0)+(COUNTIF(AE7:AN7,19)>0)+(COUNTIF(AE7:AN7,20)>0) | BV7: =IF(ISNUMBER(MATCH($B7,AE7:AN7,0)),1,0) | BW7: =IF(BV7=1,0,BW6+1) | BX7: =(COUNTIF(AO7:AY7,1)>0)+(COUNTIF(AO7:AY7,2)>0)+(COUNTIF(AO7:AY7,3)>0)+(COUNTIF(AO7:AY7,4)>0)+(COUNTIF(AO7:AY7,5)>0)+(COUNTIF(AO7:AY7,6)>0)+(COUNTIF(AO7:AY7,7)>0)+(COUNTIF(AO7:AY7,8)>0)+(COUNTIF(AO7:AY7,9)>0)+(COUNTIF(AO7:AY7,10)>0)+(COUNTIF(AO7:AY7,11)>0)+(COUNTIF(AO7:AY7,12)>0)+(COUNTIF(AO7:AY7,13)>0)+(COUNTIF(AO7:AY7,14)>0)+(COUNTIF(AO7:AY7,15)>0)+(COUNTIF(AO7:AY7,16)>0)+(COUNTIF(AO7:AY7,17)>0)+(COUNTIF(AO7:AY7,18)>0)+(COUNTIF(AO7:AY7,19)>0)+(COUNTIF(AO7:AY7,20)>0) | BY7: =IF(ISNUMBER(MATCH($B7,AO7:AY7,0)),1,0) | BZ7: =IF(BY7=1,0,BZ6+1) | CA7: =(COUNTIF(AZ7:BK7,1)>0)+(COUNTIF(AZ7:BK7,2)>0)+(COUNTIF(AZ7:BK7,3)>0)+(COUNTIF(AZ7:BK7,4)>0)+(COUNTIF(AZ7:BK7,5)>0)+(COUNTIF(AZ7:BK7,6)>0)+(COUNTIF(AZ7:BK7,7)>0)+(COUNTIF(AZ7:BK7,8)>0)+(COUNTIF(AZ7:BK7,9)>0)+(COUNTIF(AZ7:BK7,10)>0)+(COUNTIF(AZ7:BK7,11)>0)+(COUNTIF(AZ7:BK7,12)>0)+(COUNTIF(AZ7:BK7,13)>0)+(COUNTIF(AZ7:BK7,14)>0)+(COUNTIF(AZ7:BK7,15)>0)+(COUNTIF(AZ7:BK7,16)>0)+(COUNTIF(AZ7:BK7,17)>0)+(COUNTIF(AZ7:BK7,18)>0)+(COUNTIF(AZ7:BK7,19)>0)+(COUNTIF(AZ7:BK7,20)>0) | CB7: =IF(ISNUMBER(MATCH($B7,AZ7:BK7,0)),1,0) | CC7: =IF(CB7=1,0,CC6+1)
A8: 2026-05-05 13:00 | B8: 1 | C8: 10 | D8: 9 | E8: 5 | F8: 1 | G8: 5 | H8: 1 | I8: 5 | J8: 5 | K8: 19 | L8: 14 | M8: 5 | N8: 2 | O8: 20 | P8: 13 | Q8: 3 | R8: 17 | S8: 4 | T8: 16 | U8: 14 | V8: 10 | W8: 9 | X8: 5 | Y8: 1 | Z8: 19 | AA8: 14 | AB8: 2 | AC8: 20 | AD8: 13 | AE8: 10 | AF8: 9 | AG8: 5 | AH8: 1 | AI8: 19 | AJ8: 14 | AK8: 2 | AL8: 20 | AM8: 13 | AN8: 3 | AO8: 10 | AP8: 9 | AQ8: 5 | AR8: 1 | AS8: 19 | AT8: 14 | AU8: 2 | AV8: 20 | AW8: 13 | AX8: 3 | AY8: 17 | AZ8: 10 | BA8: 9 | BB8: 5 | BC8: 1 | BD8: 19 | BE8: 14 | BF8: 2 | BG8: 20 | BH8: 13 | BI8: 3 | BJ8: 17 | BK8: 4 | BL8: =(COUNTIF(C8:L8,1)>0)+(COUNTIF(C8:L8,2)>0)+(COUNTIF(C8:L8,3)>0)+(COUNTIF(C8:L8,4)>0)+(COUNTIF(C8:L8,5)>0)+(COUNTIF(C8:L8,6)>0)+(COUNTIF(C8:L8,7)>0)+(COUNTIF(C8:L8,8)>0)+(COUNTIF(C8:L8,9)>0)+(COUNTIF(C8:L8,10)>0)+(COUNTIF(C8:L8,11)>0)+(COUNTIF(C8:L8,12)>0)+(COUNTIF(C8:L8,13)>0)+(COUNTIF(C8:L8,14)>0)+(COUNTIF(C8:L8,15)>0)+(COUNTIF(C8:L8,16)>0)+(COUNTIF(C8:L8,17)>0)+(COUNTIF(C8:L8,18)>0)+(COUNTIF(C8:L8,19)>0)+(COUNTIF(C8:L8,20)>0) | BM8: =IF(ISNUMBER(MATCH($B8,C8:L8,0)),1,0) | BN8: =IF(BM8=1,0,BN7+1) | BO8: =(COUNTIF(M8:U8,1)>0)+(COUNTIF(M8:U8,2)>0)+(COUNTIF(M8:U8,3)>0)+(COUNTIF(M8:U8,4)>0)+(COUNTIF(M8:U8,5)>0)+(COUNTIF(M8:U8,6)>0)+(COUNTIF(M8:U8,7)>0)+(COUNTIF(M8:U8,8)>0)+(COUNTIF(M8:U8,9)>0)+(COUNTIF(M8:U8,10)>0)+(COUNTIF(M8:U8,11)>0)+(COUNTIF(M8:U8,12)>0)+(COUNTIF(M8:U8,13)>0)+(COUNTIF(M8:U8,14)>0)+(COUNTIF(M8:U8,15)>0)+(COUNTIF(M8:U8,16)>0)+(COUNTIF(M8:U8,17)>0)+(COUNTIF(M8:U8,18)>0)+(COUNTIF(M8:U8,19)>0)+(COUNTIF(M8:U8,20)>0) | BP8: =IF(ISNUMBER(MATCH($B8,M8:U8,0)),1,0) | BQ8: =IF(BP8=1,0,BQ7+1) | BR8: =(COUNTIF(V8:AD8,1)>0)+(COUNTIF(V8:AD8,2)>0)+(COUNTIF(V8:AD8,3)>0)+(COUNTIF(V8:AD8,4)>0)+(COUNTIF(V8:AD8,5)>0)+(COUNTIF(V8:AD8,6)>0)+(COUNTIF(V8:AD8,7)>0)+(COUNTIF(V8:AD8,8)>0)+(COUNTIF(V8:AD8,9)>0)+(COUNTIF(V8:AD8,10)>0)+(COUNTIF(V8:AD8,11)>0)+(COUNTIF(V8:AD8,12)>0)+(COUNTIF(V8:AD8,13)>0)+(COUNTIF(V8:AD8,14)>0)+(COUNTIF(V8:AD8,15)>0)+(COUNTIF(V8:AD8,16)>0)+(COUNTIF(V8:AD8,17)>0)+(COUNTIF(V8:AD8,18)>0)+(COUNTIF(V8:AD8,19)>0)+(COUNTIF(V8:AD8,20)>0) | BS8: =IF(ISNUMBER(MATCH($B8,V8:AD8,0)),1,0) | BT8: =IF(BS8=1,0,BT7+1) | BU8: =(COUNTIF(AE8:AN8,1)>0)+(COUNTIF(AE8:AN8,2)>0)+(COUNTIF(AE8:AN8,3)>0)+(COUNTIF(AE8:AN8,4)>0)+(COUNTIF(AE8:AN8,5)>0)+(COUNTIF(AE8:AN8,6)>0)+(COUNTIF(AE8:AN8,7)>0)+(COUNTIF(AE8:AN8,8)>0)+(COUNTIF(AE8:AN8,9)>0)+(COUNTIF(AE8:AN8,10)>0)+(COUNTIF(AE8:AN8,11)>0)+(COUNTIF(AE8:AN8,12)>0)+(COUNTIF(AE8:AN8,13)>0)+(COUNTIF(AE8:AN8,14)>0)+(COUNTIF(AE8:AN8,15)>0)+(COUNTIF(AE8:AN8,16)>0)+(COUNTIF(AE8:AN8,17)>0)+(COUNTIF(AE8:AN8,18)>0)+(COUNTIF(AE8:AN8,19)>0)+(COUNTIF(AE8:AN8,20)>0) | BV8: =IF(ISNUMBER(MATCH($B8,AE8:AN8,0)),1,0) | BW8: =IF(BV8=1,0,BW7+1) | BX8: =(COUNTIF(AO8:AY8,1)>0)+(COUNTIF(AO8:AY8,2)>0)+(COUNTIF(AO8:AY8,3)>0)+(COUNTIF(AO8:AY8,4)>0)+(COUNTIF(AO8:AY8,5)>0)+(COUNTIF(AO8:AY8,6)>0)+(COUNTIF(AO8:AY8,7)>0)+(COUNTIF(AO8:AY8,8)>0)+(COUNTIF(AO8:AY8,9)>0)+(COUNTIF(AO8:AY8,10)>0)+(COUNTIF(AO8:AY8,11)>0)+(COUNTIF(AO8:AY8,12)>0)+(COUNTIF(AO8:AY8,13)>0)+(COUNTIF(AO8:AY8,14)>0)+(COUNTIF(AO8:AY8,15)>0)+(COUNTIF(AO8:AY8,16)>0)+(COUNTIF(AO8:AY8,17)>0)+(COUNTIF(AO8:AY8,18)>0)+(COUNTIF(AO8:AY8,19)>0)+(COUNTIF(AO8:AY8,20)>0) | BY8: =IF(ISNUMBER(MATCH($B8,AO8:AY8,0)),1,0) | BZ8: =IF(BY8=1,0,BZ7+1) | CA8: =(COUNTIF(AZ8:BK8,1)>0)+(COUNTIF(AZ8:BK8,2)>0)+(COUNTIF(AZ8:BK8,3)>0)+(COUNTIF(AZ8:BK8,4)>0)+(COUNTIF(AZ8:BK8,5)>0)+(COUNTIF(AZ8:BK8,6)>0)+(COUNTIF(AZ8:BK8,7)>0)+(COUNTIF(AZ8:BK8,8)>0)+(COUNTIF(AZ8:BK8,9)>0)+(COUNTIF(AZ8:BK8,10)>0)+(COUNTIF(AZ8:BK8,11)>0)+(COUNTIF(AZ8:BK8,12)>0)+(COUNTIF(AZ8:BK8,13)>0)+(COUNTIF(AZ8:BK8,14)>0)+(COUNTIF(AZ8:BK8,15)>0)+(COUNTIF(AZ8:BK8,16)>0)+(COUNTIF(AZ8:BK8,17)>0)+(COUNTIF(AZ8:BK8,18)>0)+(COUNTIF(AZ8:BK8,19)>0)+(COUNTIF(AZ8:BK8,20)>0) | CB8: =IF(ISNUMBER(MATCH($B8,AZ8:BK8,0)),1,0) | CC8: =IF(CB8=1,0,CC7+1)
A9: 2026-05-05 14:00 | B9: 18 | C9: 12 | D9: 11 | E9: 8 | F9: 14 | G9: 16 | H9: 18 | I9: 18 | J9: 6 | K9: 10 | L9: 7 | M9: 17 | N9: 2 | O9: 13 | P9: 15 | Q9: 5 | R9: 20 | S9: 3 | T9: 12 | U9: 8 | V9: 12 | W9: 11 | X9: 8 | Y9: 14 | Z9: 16 | AA9: 18 | AB9: 6 | AC9: 10 | AD9: 7 | AE9: 12 | AF9: 11 | AG9: 8 | AH9: 14 | AI9: 16 | AJ9: 18 | AK9: 6 | AL9: 10 | AM9: 7 | AN9: 17 | AO9: 12 | AP9: 11 | AQ9: 8 | AR9: 14 | AS9: 16 | AT9: 18 | AU9: 6 | AV9: 10 | AW9: 7 | AX9: 17 | AY9: 2 | AZ9: 12 | BA9: 11 | BB9: 8 | BC9: 14 | BD9: 16 | BE9: 18 | BF9: 6 | BG9: 10 | BH9: 7 | BI9: 17 | BJ9: 2 | BK9: 13 | BL9: =(COUNTIF(C9:L9,1)>0)+(COUNTIF(C9:L9,2)>0)+(COUNTIF(C9:L9,3)>0)+(COUNTIF(C9:L9,4)>0)+(COUNTIF(C9:L9,5)>0)+(COUNTIF(C9:L9,6)>0)+(COUNTIF(C9:L9,7)>0)+(COUNTIF(C9:L9,8)>0)+(COUNTIF(C9:L9,9)>0)+(COUNTIF(C9:L9,10)>0)+(COUNTIF(C9:L9,11)>0)+(COUNTIF(C9:L9,12)>0)+(COUNTIF(C9:L9,13)>0)+(COUNTIF(C9:L9,14)>0)+(COUNTIF(C9:L9,15)>0)+(COUNTIF(C9:L9,16)>0)+(COUNTIF(C9:L9,17)>0)+(COUNTIF(C9:L9,18)>0)+(COUNTIF(C9:L9,19)>0)+(COUNTIF(C9:L9,20)>0) | BM9: =IF(ISNUMBER(MATCH($B9,C9:L9,0)),1,0) | BN9: =IF(BM9=1,0,BN8+1) | BO9: =(COUNTIF(M9:U9,1)>0)+(COUNTIF(M9:U9,2)>0)+(COUNTIF(M9:U9,3)>0)+(COUNTIF(M9:U9,4)>0)+(COUNTIF(M9:U9,5)>0)+(COUNTIF(M9:U9,6)>0)+(COUNTIF(M9:U9,7)>0)+(COUNTIF(M9:U9,8)>0)+(COUNTIF(M9:U9,9)>0)+(COUNTIF(M9:U9,10)>0)+(COUNTIF(M9:U9,11)>0)+(COUNTIF(M9:U9,12)>0)+(COUNTIF(M9:U9,13)>0)+(COUNTIF(M9:U9,14)>0)+(COUNTIF(M9:U9,15)>0)+(COUNTIF(M9:U9,16)>0)+(COUNTIF(M9:U9,17)>0)+(COUNTIF(M9:U9,18)>0)+(COUNTIF(M9:U9,19)>0)+(COUNTIF(M9:U9,20)>0) | BP9: =IF(ISNUMBER(MATCH($B9,M9:U9,0)),1,0) | BQ9: =IF(BP9=1,0,BQ8+1) | BR9: =(COUNTIF(V9:AD9,1)>0)+(COUNTIF(V9:AD9,2)>0)+(COUNTIF(V9:AD9,3)>0)+(COUNTIF(V9:AD9,4)>0)+(COUNTIF(V9:AD9,5)>0)+(COUNTIF(V9:AD9,6)>0)+(COUNTIF(V9:AD9,7)>0)+(COUNTIF(V9:AD9,8)>0)+(COUNTIF(V9:AD9,9)>0)+(COUNTIF(V9:AD9,10)>0)+(COUNTIF(V9:AD9,11)>0)+(COUNTIF(V9:AD9,12)>0)+(COUNTIF(V9:AD9,13)>0)+(COUNTIF(V9:AD9,14)>0)+(COUNTIF(V9:AD9,15)>0)+(COUNTIF(V9:AD9,16)>0)+(COUNTIF(V9:AD9,17)>0)+(COUNTIF(V9:AD9,18)>0)+(COUNTIF(V9:AD9,19)>0)+(COUNTIF(V9:AD9,20)>0) | BS9: =IF(ISNUMBER(MATCH($B9,V9:AD9,0)),1,0) | BT9: =IF(BS9=1,0,BT8+1) | BU9: =(COUNTIF(AE9:AN9,1)>0)+(COUNTIF(AE9:AN9,2)>0)+(COUNTIF(AE9:AN9,3)>0)+(COUNTIF(AE9:AN9,4)>0)+(COUNTIF(AE9:AN9,5)>0)+(COUNTIF(AE9:AN9,6)>0)+(COUNTIF(AE9:AN9,7)>0)+(COUNTIF(AE9:AN9,8)>0)+(COUNTIF(AE9:AN9,9)>0)+(COUNTIF(AE9:AN9,10)>0)+(COUNTIF(AE9:AN9,11)>0)+(COUNTIF(AE9:AN9,12)>0)+(COUNTIF(AE9:AN9,13)>0)+(COUNTIF(AE9:AN9,14)>0)+(COUNTIF(AE9:AN9,15)>0)+(COUNTIF(AE9:AN9,16)>0)+(COUNTIF(AE9:AN9,17)>0)+(COUNTIF(AE9:AN9,18)>0)+(COUNTIF(AE9:AN9,19)>0)+(COUNTIF(AE9:AN9,20)>0) | BV9: =IF(ISNUMBER(MATCH($B9,AE9:AN9,0)),1,0) | BW9: =IF(BV9=1,0,BW8+1) | BX9: =(COUNTIF(AO9:AY9,1)>0)+(COUNTIF(AO9:AY9,2)>0)+(COUNTIF(AO9:AY9,3)>0)+(COUNTIF(AO9:AY9,4)>0)+(COUNTIF(AO9:AY9,5)>0)+(COUNTIF(AO9:AY9,6)>0)+(COUNTIF(AO9:AY9,7)>0)+(COUNTIF(AO9:AY9,8)>0)+(COUNTIF(AO9:AY9,9)>0)+(COUNTIF(AO9:AY9,10)>0)+(COUNTIF(AO9:AY9,11)>0)+(COUNTIF(AO9:AY9,12)>0)+(COUNTIF(AO9:AY9,13)>0)+(COUNTIF(AO9:AY9,14)>0)+(COUNTIF(AO9:AY9,15)>0)+(COUNTIF(AO9:AY9,16)>0)+(COUNTIF(AO9:AY9,17)>0)+(COUNTIF(AO9:AY9,18)>0)+(COUNTIF(AO9:AY9,19)>0)+(COUNTIF(AO9:AY9,20)>0) | BY9: =IF(ISNUMBER(MATCH($B9,AO9:AY9,0)),1,0) | BZ9: =IF(BY9=1,0,BZ8+1) | CA9: =(COUNTIF(AZ9:BK9,1)>0)+(COUNTIF(AZ9:BK9,2)>0)+(COUNTIF(AZ9:BK9,3)>0)+(COUNTIF(AZ9:BK9,4)>0)+(COUNTIF(AZ9:BK9,5)>0)+(COUNTIF(AZ9:BK9,6)>0)+(COUNTIF(AZ9:BK9,7)>0)+(COUNTIF(AZ9:BK9,8)>0)+(COUNTIF(AZ9:BK9,9)>0)+(COUNTIF(AZ9:BK9,10)>0)+(COUNTIF(AZ9:BK9,11)>0)+(COUNTIF(AZ9:BK9,12)>0)+(COUNTIF(AZ9:BK9,13)>0)+(COUNTIF(AZ9:BK9,14)>0)+(COUNTIF(AZ9:BK9,15)>0)+(COUNTIF(AZ9:BK9,16)>0)+(COUNTIF(AZ9:BK9,17)>0)+(COUNTIF(AZ9:BK9,18)>0)+(COUNTIF(AZ9:BK9,19)>0)+(COUNTIF(AZ9:BK9,20)>0) | CB9: =IF(ISNUMBER(MATCH($B9,AZ9:BK9,0)),1,0) | CC9: =IF(CB9=1,0,CC8+1)
A10: 2026-05-05 15:00 | B10: 5 | C10: 1 | D10: 3 | E10: 19 | F10: 11 | G10: 9 | H10: 15 | I10: 16 | J10: 8 | K10: 9 | L10: 2 | M10: 13 | N10: 20 | O10: 3 | P10: 5 | Q10: 17 | R10: 2 | S10: 8 | T10: 7 | U10: 14 | V10: 1 | W10: 3 | X10: 19 | Y10: 11 | Z10: 9 | AA10: 15 | AB10: 16 | AC10: 8 | AD10: 2 | AE10: 1 | AF10: 3 | AG10: 19 | AH10: 11 | AI10: 9 | AJ10: 15 | AK10: 16 | AL10: 8 | AM10: 2 | AN10: 13 | AO10: 1 | AP10: 3 | AQ10: 19 | AR10: 11 | AS10: 9 | AT10: 15 | AU10: 16 | AV10: 8 | AW10: 2 | AX10: 13 | AY10: 20 | AZ10: 1 | BA10: 3 | BB10: 19 | BC10: 11 | BD10: 9 | BE10: 15 | BF10: 16 | BG10: 8 | BH10: 2 | BI10: 13 | BJ10: 20 | BK10: 5 | BL10: =(COUNTIF(C10:L10,1)>0)+(COUNTIF(C10:L10,2)>0)+(COUNTIF(C10:L10,3)>0)+(COUNTIF(C10:L10,4)>0)+(COUNTIF(C10:L10,5)>0)+(COUNTIF(C10:L10,6)>0)+(COUNTIF(C10:L10,7)>0)+(COUNTIF(C10:L10,8)>0)+(COUNTIF(C10:L10,9)>0)+(COUNTIF(C10:L10,10)>0)+(COUNTIF(C10:L10,11)>0)+(COUNTIF(C10:L10,12)>0)+(COUNTIF(C10:L10,13)>0)+(COUNTIF(C10:L10,14)>0)+(COUNTIF(C10:L10,15)>0)+(COUNTIF(C10:L10,16)>0)+(COUNTIF(C10:L10,17)>0)+(COUNTIF(C10:L10,18)>0)+(COUNTIF(C10:L10,19)>0)+(COUNTIF(C10:L10,20)>0) | BM10: =IF(ISNUMBER(MATCH($B10,C10:L10,0)),1,0) | BN10: =IF(BM10=1,0,BN9+1) | BO10: =(COUNTIF(M10:U10,1)>0)+(COUNTIF(M10:U10,2)>0)+(COUNTIF(M10:U10,3)>0)+(COUNTIF(M10:U10,4)>0)+(COUNTIF(M10:U10,5)>0)+(COUNTIF(M10:U10,6)>0)+(COUNTIF(M10:U10,7)>0)+(COUNTIF(M10:U10,8)>0)+(COUNTIF(M10:U10,9)>0)+(COUNTIF(M10:U10,10)>0)+(COUNTIF(M10:U10,11)>0)+(COUNTIF(M10:U10,12)>0)+(COUNTIF(M10:U10,13)>0)+(COUNTIF(M10:U10,14)>0)+(COUNTIF(M10:U10,15)>0)+(COUNTIF(M10:U10,16)>0)+(COUNTIF(M10:U10,17)>0)+(COUNTIF(M10:U10,18)>0)+(COUNTIF(M10:U10,19)>0)+(COUNTIF(M10:U10,20)>0) | BP10: =IF(ISNUMBER(MATCH($B10,M10:U10,0)),1,0) | BQ10: =IF(BP10=1,0,BQ9+1) | BR10: =(COUNTIF(V10:AD10,1)>0)+(COUNTIF(V10:AD10,2)>0)+(COUNTIF(V10:AD10,3)>0)+(COUNTIF(V10:AD10,4)>0)+(COUNTIF(V10:AD10,5)>0)+(COUNTIF(V10:AD10,6)>0)+(COUNTIF(V10:AD10,7)>0)+(COUNTIF(V10:AD10,8)>0)+(COUNTIF(V10:AD10,9)>0)+(COUNTIF(V10:AD10,10)>0)+(COUNTIF(V10:AD10,11)>0)+(COUNTIF(V10:AD10,12)>0)+(COUNTIF(V10:AD10,13)>0)+(COUNTIF(V10:AD10,14)>0)+(COUNTIF(V10:AD10,15)>0)+(COUNTIF(V10:AD10,16)>0)+(COUNTIF(V10:AD10,17)>0)+(COUNTIF(V10:AD10,18)>0)+(COUNTIF(V10:AD10,19)>0)+(COUNTIF(V10:AD10,20)>0) | BS10: =IF(ISNUMBER(MATCH($B10,V10:AD10,0)),1,0) | BT10: =IF(BS10=1,0,BT9+1) | BU10: =(COUNTIF(AE10:AN10,1)>0)+(COUNTIF(AE10:AN10,2)>0)+(COUNTIF(AE10:AN10,3)>0)+(COUNTIF(AE10:AN10,4)>0)+(COUNTIF(AE10:AN10,5)>0)+(COUNTIF(AE10:AN10,6)>0)+(COUNTIF(AE10:AN10,7)>0)+(COUNTIF(AE10:AN10,8)>0)+(COUNTIF(AE10:AN10,9)>0)+(COUNTIF(AE10:AN10,10)>0)+(COUNTIF(AE10:AN10,11)>0)+(COUNTIF(AE10:AN10,12)>0)+(COUNTIF(AE10:AN10,13)>0)+(COUNTIF(AE10:AN10,14)>0)+(COUNTIF(AE10:AN10,15)>0)+(COUNTIF(AE10:AN10,16)>0)+(COUNTIF(AE10:AN10,17)>0)+(COUNTIF(AE10:AN10,18)>0)+(COUNTIF(AE10:AN10,19)>0)+(COUNTIF(AE10:AN10,20)>0) | BV10: =IF(ISNUMBER(MATCH($B10,AE10:AN10,0)),1,0) | BW10: =IF(BV10=1,0,BW9+1) | BX10: =(COUNTIF(AO10:AY10,1)>0)+(COUNTIF(AO10:AY10,2)>0)+(COUNTIF(AO10:AY10,3)>0)+(COUNTIF(AO10:AY10,4)>0)+(COUNTIF(AO10:AY10,5)>0)+(COUNTIF(AO10:AY10,6)>0)+(COUNTIF(AO10:AY10,7)>0)+(COUNTIF(AO10:AY10,8)>0)+(COUNTIF(AO10:AY10,9)>0)+(COUNTIF(AO10:AY10,10)>0)+(COUNTIF(AO10:AY10,11)>0)+(COUNTIF(AO10:AY10,12)>0)+(COUNTIF(AO10:AY10,13)>0)+(COUNTIF(AO10:AY10,14)>0)+(COUNTIF(AO10:AY10,15)>0)+(COUNTIF(AO10:AY10,16)>0)+(COUNTIF(AO10:AY10,17)>0)+(COUNTIF(AO10:AY10,18)>0)+(COUNTIF(AO10:AY10,19)>0)+(COUNTIF(AO10:AY10,20)>0) | BY10: =IF(ISNUMBER(MATCH($B10,AO10:AY10,0)),1,0) | BZ10: =IF(BY10=1,0,BZ9+1) | CA10: =(COUNTIF(AZ10:BK10,1)>0)+(COUNTIF(AZ10:BK10,2)>0)+(COUNTIF(AZ10:BK10,3)>0)+(COUNTIF(AZ10:BK10,4)>0)+(COUNTIF(AZ10:BK10,5)>0)+(COUNTIF(AZ10:BK10,6)>0)+(COUNTIF(AZ10:BK10,7)>0)+(COUNTIF(AZ10:BK10,8)>0)+(COUNTIF(AZ10:BK10,9)>0)+(COUNTIF(AZ10:BK10,10)>0)+(COUNTIF(AZ10:BK10,11)>0)+(COUNTIF(AZ10:BK10,12)>0)+(COUNTIF(AZ10:BK10,13)>0)+(COUNTIF(AZ10:BK10,14)>0)+(COUNTIF(AZ10:BK10,15)>0)+(COUNTIF(AZ10:BK10,16)>0)+(COUNTIF(AZ10:BK10,17)>0)+(COUNTIF(AZ10:BK10,18)>0)+(COUNTIF(AZ10:BK10,19)>0)+(COUNTIF(AZ10:BK10,20)>0) | CB10: =IF(ISNUMBER(MATCH($B10,AZ10:BK10,0)),1,0) | CC10: =IF(CB10=1,0,CC9+1)
A11: 2026-05-05 16:00 | B11: 6 | C11: 5 | D11: 17 | E11: 17 | F11: 14 | G11: 7 | H11: 20 | I11: 2 | J11: 14 | K11: 18 | L11: 7 | M11: 19 | N11: 13 | O11: 17 | P11: 18 | Q11: 11 | R11: 2 | S11: 5 | T11: 3 | U11: 15 | V11: 5 | W11: 17 | X11: 14 | Y11: 7 | Z11: 20 | AA11: 2 | AB11: 18 | AC11: 19 | AD11: 13 | AE11: 5 | AF11: 17 | AG11: 14 | AH11: 7 | AI11: 20 | AJ11: 2 | AK11: 18 | AL11: 19 | AM11: 13 | AN11: 11 | AO11: 5 | AP11: 17 | AQ11: 14 | AR11: 7 | AS11: 20 | AT11: 2 | AU11: 18 | AV11: 19 | AW11: 13 | AX11: 11 | AY11: 3 | AZ11: 5 | BA11: 17 | BB11: 14 | BC11: 7 | BD11: 20 | BE11: 2 | BF11: 18 | BG11: 19 | BH11: 13 | BI11: 11 | BJ11: 3 | BK11: 15 | BL11: =(COUNTIF(C11:L11,1)>0)+(COUNTIF(C11:L11,2)>0)+(COUNTIF(C11:L11,3)>0)+(COUNTIF(C11:L11,4)>0)+(COUNTIF(C11:L11,5)>0)+(COUNTIF(C11:L11,6)>0)+(COUNTIF(C11:L11,7)>0)+(COUNTIF(C11:L11,8)>0)+(COUNTIF(C11:L11,9)>0)+(COUNTIF(C11:L11,10)>0)+(COUNTIF(C11:L11,11)>0)+(COUNTIF(C11:L11,12)>0)+(COUNTIF(C11:L11,13)>0)+(COUNTIF(C11:L11,14)>0)+(COUNTIF(C11:L11,15)>0)+(COUNTIF(C11:L11,16)>0)+(COUNTIF(C11:L11,17)>0)+(COUNTIF(C11:L11,18)>0)+(COUNTIF(C11:L11,19)>0)+(COUNTIF(C11:L11,20)>0) | BM11: =IF(ISNUMBER(MATCH($B11,C11:L11,0)),1,0) | BN11: =IF(BM11=1,0,BN10+1) | BO11: =(COUNTIF(M11:U11,1)>0)+(COUNTIF(M11:U11,2)>0)+(COUNTIF(M11:U11,3)>0)+(COUNTIF(M11:U11,4)>0)+(COUNTIF(M11:U11,5)>0)+(COUNTIF(M11:U11,6)>0)+(COUNTIF(M11:U11,7)>0)+(COUNTIF(M11:U11,8)>0)+(COUNTIF(M11:U11,9)>0)+(COUNTIF(M11:U11,10)>0)+(COUNTIF(M11:U11,11)>0)+(COUNTIF(M11:U11,12)>0)+(COUNTIF(M11:U11,13)>0)+(COUNTIF(M11:U11,14)>0)+(COUNTIF(M11:U11,15)>0)+(COUNTIF(M11:U11,16)>0)+(COUNTIF(M11:U11,17)>0)+(COUNTIF(M11:U11,18)>0)+(COUNTIF(M11:U11,19)>0)+(COUNTIF(M11:U11,20)>0) | BP11: =IF(ISNUMBER(MATCH($B11,M11:U11,0)),1,0) | BQ11: =IF(BP11=1,0,BQ10+1) | BR11: =(COUNTIF(V11:AD11,1)>0)+(COUNTIF(V11:AD11,2)>0)+(COUNTIF(V11:AD11,3)>0)+(COUNTIF(V11:AD11,4)>0)+(COUNTIF(V11:AD11,5)>0)+(COUNTIF(V11:AD11,6)>0)+(COUNTIF(V11:AD11,7)>0)+(COUNTIF(V11:AD11,8)>0)+(COUNTIF(V11:AD11,9)>0)+(COUNTIF(V11:AD11,10)>0)+(COUNTIF(V11:AD11,11)>0)+(COUNTIF(V11:AD11,12)>0)+(COUNTIF(V11:AD11,13)>0)+(COUNTIF(V11:AD11,14)>0)+(COUNTIF(V11:AD11,15)>0)+(COUNTIF(V11:AD11,16)>0)+(COUNTIF(V11:AD11,17)>0)+(COUNTIF(V11:AD11,18)>0)+(COUNTIF(V11:AD11,19)>0)+(COUNTIF(V11:AD11,20)>0) | BS11: =IF(ISNUMBER(MATCH($B11,V11:AD11,0)),1,0) | BT11: =IF(BS11=1,0,BT10+1) | BU11: =(COUNTIF(AE11:AN11,1)>0)+(COUNTIF(AE11:AN11,2)>0)+(COUNTIF(AE11:AN11,3)>0)+(COUNTIF(AE11:AN11,4)>0)+(COUNTIF(AE11:AN11,5)>0)+(COUNTIF(AE11:AN11,6)>0)+(COUNTIF(AE11:AN11,7)>0)+(COUNTIF(AE11:AN11,8)>0)+(COUNTIF(AE11:AN11,9)>0)+(COUNTIF(AE11:AN11,10)>0)+(COUNTIF(AE11:AN11,11)>0)+(COUNTIF(AE11:AN11,12)>0)+(COUNTIF(AE11:AN11,13)>0)+(COUNTIF(AE11:AN11,14)>0)+(COUNTIF(AE11:AN11,15)>0)+(COUNTIF(AE11:AN11,16)>0)+(COUNTIF(AE11:AN11,17)>0)+(COUNTIF(AE11:AN11,18)>0)+(COUNTIF(AE11:AN11,19)>0)+(COUNTIF(AE11:AN11,20)>0) | BV11: =IF(ISNUMBER(MATCH($B11,AE11:AN11,0)),1,0) | BW11: =IF(BV11=1,0,BW10+1) | BX11: =(COUNTIF(AO11:AY11,1)>0)+(COUNTIF(AO11:AY11,2)>0)+(COUNTIF(AO11:AY11,3)>0)+(COUNTIF(AO11:AY11,4)>0)+(COUNTIF(AO11:AY11,5)>0)+(COUNTIF(AO11:AY11,6)>0)+(COUNTIF(AO11:AY11,7)>0)+(COUNTIF(AO11:AY11,8)>0)+(COUNTIF(AO11:AY11,9)>0)+(COUNTIF(AO11:AY11,10)>0)+(COUNTIF(AO11:AY11,11)>0)+(COUNTIF(AO11:AY11,12)>0)+(COUNTIF(AO11:AY11,13)>0)+(COUNTIF(AO11:AY11,14)>0)+(COUNTIF(AO11:AY11,15)>0)+(COUNTIF(AO11:AY11,16)>0)+(COUNTIF(AO11:AY11,17)>0)+(COUNTIF(AO11:AY11,18)>0)+(COUNTIF(AO11:AY11,19)>0)+(COUNTIF(AO11:AY11,20)>0) | BY11: =IF(ISNUMBER(MATCH($B11,AO11:AY11,0)),1,0) | BZ11: =IF(BY11=1,0,BZ10+1) | CA11: =(COUNTIF(AZ11:BK11,1)>0)+(COUNTIF(AZ11:BK11,2)>0)+(COUNTIF(AZ11:BK11,3)>0)+(COUNTIF(AZ11:BK11,4)>0)+(COUNTIF(AZ11:BK11,5)>0)+(COUNTIF(AZ11:BK11,6)>0)+(COUNTIF(AZ11:BK11,7)>0)+(COUNTIF(AZ11:BK11,8)>0)+(COUNTIF(AZ11:BK11,9)>0)+(COUNTIF(AZ11:BK11,10)>0)+(COUNTIF(AZ11:BK11,11)>0)+(COUNTIF(AZ11:BK11,12)>0)+(COUNTIF(AZ11:BK11,13)>0)+(COUNTIF(AZ11:BK11,14)>0)+(COUNTIF(AZ11:BK11,15)>0)+(COUNTIF(AZ11:BK11,16)>0)+(COUNTIF(AZ11:BK11,17)>0)+(COUNTIF(AZ11:BK11,18)>0)+(COUNTIF(AZ11:BK11,19)>0)+(COUNTIF(AZ11:BK11,20)>0) | CB11: =IF(ISNUMBER(MATCH($B11,AZ11:BK11,0)),1,0) | CC11: =IF(CB11=1,0,CC10+1)
A12: 2026-05-05 17:00 | B12: 12 | C12: 20 | D12: 11 | E12: 11 | F12: 17 | G12: 9 | H12: 2 | I12: 10 | J12: 18 | K12: 4 | L12: 3 | M12: 20 | N12: 1 | O12: 17 | P12: 3 | Q12: 5 | R12: 2 | S12: 8 | T12: 15 | U12: 6 | V12: 20 | W12: 11 | X12: 17 | Y12: 9 | Z12: 2 | AA12: 10 | AB12: 18 | AC12: 4 | AD12: 3 | AE12: 20 | AF12: 11 | AG12: 17 | AH12: 9 | AI12: 2 | AJ12: 10 | AK12: 18 | AL12: 4 | AM12: 3 | AN12: 1 | AO12: 20 | AP12: 11 | AQ12: 17 | AR12: 9 | AS12: 2 | AT12: 10 | AU12: 18 | AV12: 4 | AW12: 3 | AX12: 1 | AY12: 5 | AZ12: 20 | BA12: 11 | BB12: 17 | BC12: 9 | BD12: 2 | BE12: 10 | BF12: 18 | BG12: 4 | BH12: 3 | BI12: 1 | BJ12: 5 | BK12: 8 | BL12: =(COUNTIF(C12:L12,1)>0)+(COUNTIF(C12:L12,2)>0)+(COUNTIF(C12:L12,3)>0)+(COUNTIF(C12:L12,4)>0)+(COUNTIF(C12:L12,5)>0)+(COUNTIF(C12:L12,6)>0)+(COUNTIF(C12:L12,7)>0)+(COUNTIF(C12:L12,8)>0)+(COUNTIF(C12:L12,9)>0)+(COUNTIF(C12:L12,10)>0)+(COUNTIF(C12:L12,11)>0)+(COUNTIF(C12:L12,12)>0)+(COUNTIF(C12:L12,13)>0)+(COUNTIF(C12:L12,14)>0)+(COUNTIF(C12:L12,15)>0)+(COUNTIF(C12:L12,16)>0)+(COUNTIF(C12:L12,17)>0)+(COUNTIF(C12:L12,18)>0)+(COUNTIF(C12:L12,19)>0)+(COUNTIF(C12:L12,20)>0) | BM12: =IF(ISNUMBER(MATCH($B12,C12:L12,0)),1,0) | BN12: =IF(BM12=1,0,BN11+1) | BO12: =(COUNTIF(M12:U12,1)>0)+(COUNTIF(M12:U12,2)>0)+(COUNTIF(M12:U12,3)>0)+(COUNTIF(M12:U12,4)>0)+(COUNTIF(M12:U12,5)>0)+(COUNTIF(M12:U12,6)>0)+(COUNTIF(M12:U12,7)>0)+(COUNTIF(M12:U12,8)>0)+(COUNTIF(M12:U12,9)>0)+(COUNTIF(M12:U12,10)>0)+(COUNTIF(M12:U12,11)>0)+(COUNTIF(M12:U12,12)>0)+(COUNTIF(M12:U12,13)>0)+(COUNTIF(M12:U12,14)>0)+(COUNTIF(M12:U12,15)>0)+(COUNTIF(M12:U12,16)>0)+(COUNTIF(M12:U12,17)>0)+(COUNTIF(M12:U12,18)>0)+(COUNTIF(M12:U12,19)>0)+(COUNTIF(M12:U12,20)>0) | BP12: =IF(ISNUMBER(MATCH($B12,M12:U12,0)),1,0) | BQ12: =IF(BP12=1,0,BQ11+1) | BR12: =(COUNTIF(V12:AD12,1)>0)+(COUNTIF(V12:AD12,2)>0)+(COUNTIF(V12:AD12,3)>0)+(COUNTIF(V12:AD12,4)>0)+(COUNTIF(V12:AD12,5)>0)+(COUNTIF(V12:AD12,6)>0)+(COUNTIF(V12:AD12,7)>0)+(COUNTIF(V12:AD12,8)>0)+(COUNTIF(V12:AD12,9)>0)+(COUNTIF(V12:AD12,10)>0)+(COUNTIF(V12:AD12,11)>0)+(COUNTIF(V12:AD12,12)>0)+(COUNTIF(V12:AD12,13)>0)+(COUNTIF(V12:AD12,14)>0)+(COUNTIF(V12:AD12,15)>0)+(COUNTIF(V12:AD12,16)>0)+(COUNTIF(V12:AD12,17)>0)+(COUNTIF(V12:AD12,18)>0)+(COUNTIF(V12:AD12,19)>0)+(COUNTIF(V12:AD12,20)>0) | BS12: =IF(ISNUMBER(MATCH($B12,V12:AD12,0)),1,0) | BT12: =IF(BS12=1,0,BT11+1) | BU12: =(COUNTIF(AE12:AN12,1)>0)+(COUNTIF(AE12:AN12,2)>0)+(COUNTIF(AE12:AN12,3)>0)+(COUNTIF(AE12:AN12,4)>0)+(COUNTIF(AE12:AN12,5)>0)+(COUNTIF(AE12:AN12,6)>0)+(COUNTIF(AE12:AN12,7)>0)+(COUNTIF(AE12:AN12,8)>0)+(COUNTIF(AE12:AN12,9)>0)+(COUNTIF(AE12:AN12,10)>0)+(COUNTIF(AE12:AN12,11)>0)+(COUNTIF(AE12:AN12,12)>0)+(COUNTIF(AE12:AN12,13)>0)+(COUNTIF(AE12:AN12,14)>0)+(COUNTIF(AE12:AN12,15)>0)+(COUNTIF(AE12:AN12,16)>0)+(COUNTIF(AE12:AN12,17)>0)+(COUNTIF(AE12:AN12,18)>0)+(COUNTIF(AE12:AN12,19)>0)+(COUNTIF(AE12:AN12,20)>0) | BV12: =IF(ISNUMBER(MATCH($B12,AE12:AN12,0)),1,0) | BW12: =IF(BV12=1,0,BW11+1) | BX12: =(COUNTIF(AO12:AY12,1)>0)+(COUNTIF(AO12:AY12,2)>0)+(COUNTIF(AO12:AY12,3)>0)+(COUNTIF(AO12:AY12,4)>0)+(COUNTIF(AO12:AY12,5)>0)+(COUNTIF(AO12:AY12,6)>0)+(COUNTIF(AO12:AY12,7)>0)+(COUNTIF(AO12:AY12,8)>0)+(COUNTIF(AO12:AY12,9)>0)+(COUNTIF(AO12:AY12,10)>0)+(COUNTIF(AO12:AY12,11)>0)+(COUNTIF(AO12:AY12,12)>0)+(COUNTIF(AO12:AY12,13)>0)+(COUNTIF(AO12:AY12,14)>0)+(COUNTIF(AO12:AY12,15)>0)+(COUNTIF(AO12:AY12,16)>0)+(COUNTIF(AO12:AY12,17)>0)+(COUNTIF(AO12:AY12,18)>0)+(COUNTIF(AO12:AY12,19)>0)+(COUNTIF(AO12:AY12,20)>0) | BY12: =IF(ISNUMBER(MATCH($B12,AO12:AY12,0)),1,0) | BZ12: =IF(BY12=1,0,BZ11+1) | CA12: =(COUNTIF(AZ12:BK12,1)>0)+(COUNTIF(AZ12:BK12,2)>0)+(COUNTIF(AZ12:BK12,3)>0)+(COUNTIF(AZ12:BK12,4)>0)+(COUNTIF(AZ12:BK12,5)>0)+(COUNTIF(AZ12:BK12,6)>0)+(COUNTIF(AZ12:BK12,7)>0)+(COUNTIF(AZ12:BK12,8)>0)+(COUNTIF(AZ12:BK12,9)>0)+(COUNTIF(AZ12:BK12,10)>0)+(COUNTIF(AZ12:BK12,11)>0)+(COUNTIF(AZ12:BK12,12)>0)+(COUNTIF(AZ12:BK12,13)>0)+(COUNTIF(AZ12:BK12,14)>0)+(COUNTIF(AZ12:BK12,15)>0)+(COUNTIF(AZ12:BK12,16)>0)+(COUNTIF(AZ12:BK12,17)>0)+(COUNTIF(AZ12:BK12,18)>0)+(COUNTIF(AZ12:BK12,19)>0)+(COUNTIF(AZ12:BK12,20)>0) | CB12: =IF(ISNUMBER(MATCH($B12,AZ12:BK12,0)),1,0) | CC12: =IF(CB12=1,0,CC11+1)
A13: 2026-05-05 18:00 | B13: 3 | C13: 20 | D13: 8 | E13: 3 | F13: 12 | G13: 18 | H13: 14 | I13: 17 | J13: 20 | K13: 6 | L13: 10 | M13: 11 | N13: 20 | O13: 17 | P13: 2 | Q13: 8 | R13: 14 | S13: 7 | T13: 3 | U13: 13 | V13: 20 | W13: 8 | X13: 3 | Y13: 12 | Z13: 18 | AA13: 14 | AB13: 17 | AC13: 6 | AD13: 10 | AE13: 20 | AF13: 8 | AG13: 3 | AH13: 12 | AI13: 18 | AJ13: 14 | AK13: 17 | AL13: 6 | AM13: 10 | AN13: 11 | AO13: 20 | AP13: 8 | AQ13: 3 | AR13: 12 | AS13: 18 | AT13: 14 | AU13: 17 | AV13: 6 | AW13: 10 | AX13: 11 | AY13: 2 | AZ13: 20 | BA13: 8 | BB13: 3 | BC13: 12 | BD13: 18 | BE13: 14 | BF13: 17 | BG13: 6 | BH13: 10 | BI13: 11 | BJ13: 2 | BK13: 7 | BL13: =(COUNTIF(C13:L13,1)>0)+(COUNTIF(C13:L13,2)>0)+(COUNTIF(C13:L13,3)>0)+(COUNTIF(C13:L13,4)>0)+(COUNTIF(C13:L13,5)>0)+(COUNTIF(C13:L13,6)>0)+(COUNTIF(C13:L13,7)>0)+(COUNTIF(C13:L13,8)>0)+(COUNTIF(C13:L13,9)>0)+(COUNTIF(C13:L13,10)>0)+(COUNTIF(C13:L13,11)>0)+(COUNTIF(C13:L13,12)>0)+(COUNTIF(C13:L13,13)>0)+(COUNTIF(C13:L13,14)>0)+(COUNTIF(C13:L13,15)>0)+(COUNTIF(C13:L13,16)>0)+(COUNTIF(C13:L13,17)>0)+(COUNTIF(C13:L13,18)>0)+(COUNTIF(C13:L13,19)>0)+(COUNTIF(C13:L13,20)>0) | BM13: =IF(ISNUMBER(MATCH($B13,C13:L13,0)),1,0) | BN13: =IF(BM13=1,0,BN12+1) | BO13: =(COUNTIF(M13:U13,1)>0)+(COUNTIF(M13:U13,2)>0)+(COUNTIF(M13:U13,3)>0)+(COUNTIF(M13:U13,4)>0)+(COUNTIF(M13:U13,5)>0)+(COUNTIF(M13:U13,6)>0)+(COUNTIF(M13:U13,7)>0)+(COUNTIF(M13:U13,8)>0)+(COUNTIF(M13:U13,9)>0)+(COUNTIF(M13:U13,10)>0)+(COUNTIF(M13:U13,11)>0)+(COUNTIF(M13:U13,12)>0)+(COUNTIF(M13:U13,13)>0)+(COUNTIF(M13:U13,14)>0)+(COUNTIF(M13:U13,15)>0)+(COUNTIF(M13:U13,16)>0)+(COUNTIF(M13:U13,17)>0)+(COUNTIF(M13:U13,18)>0)+(COUNTIF(M13:U13,19)>0)+(COUNTIF(M13:U13,20)>0) | BP13: =IF(ISNUMBER(MATCH($B13,M13:U13,0)),1,0) | BQ13: =IF(BP13=1,0,BQ12+1) | BR13: =(COUNTIF(V13:AD13,1)>0)+(COUNTIF(V13:AD13,2)>0)+(COUNTIF(V13:AD13,3)>0)+(COUNTIF(V13:AD13,4)>0)+(COUNTIF(V13:AD13,5)>0)+(COUNTIF(V13:AD13,6)>0)+(COUNTIF(V13:AD13,7)>0)+(COUNTIF(V13:AD13,8)>0)+(COUNTIF(V13:AD13,9)>0)+(COUNTIF(V13:AD13,10)>0)+(COUNTIF(V13:AD13,11)>0)+(COUNTIF(V13:AD13,12)>0)+(COUNTIF(V13:AD13,13)>0)+(COUNTIF(V13:AD13,14)>0)+(COUNTIF(V13:AD13,15)>0)+(COUNTIF(V13:AD13,16)>0)+(COUNTIF(V13:AD13,17)>0)+(COUNTIF(V13:AD13,18)>0)+(COUNTIF(V13:AD13,19)>0)+(COUNTIF(V13:AD13,20)>0) | BS13: =IF(ISNUMBER(MATCH($B13,V13:AD13,0)),1,0) | BT13: =IF(BS13=1,0,BT12+1) | BU13: =(COUNTIF(AE13:AN13,1)>0)+(COUNTIF(AE13:AN13,2)>0)+(COUNTIF(AE13:AN13,3)>0)+(COUNTIF(AE13:AN13,4)>0)+(COUNTIF(AE13:AN13,5)>0)+(COUNTIF(AE13:AN13,6)>0)+(COUNTIF(AE13:AN13,7)>0)+(COUNTIF(AE13:AN13,8)>0)+(COUNTIF(AE13:AN13,9)>0)+(COUNTIF(AE13:AN13,10)>0)+(COUNTIF(AE13:AN13,11)>0)+(COUNTIF(AE13:AN13,12)>0)+(COUNTIF(AE13:AN13,13)>0)+(COUNTIF(AE13:AN13,14)>0)+(COUNTIF(AE13:AN13,15)>0)+(COUNTIF(AE13:AN13,16)>0)+(COUNTIF(AE13:AN13,17)>0)+(COUNTIF(AE13:AN13,18)>0)+(COUNTIF(AE13:AN13,19)>0)+(COUNTIF(AE13:AN13,20)>0) | BV13: =IF(ISNUMBER(MATCH($B13,AE13:AN13,0)),1,0) | BW13: =IF(BV13=1,0,BW12+1) | BX13: =(COUNTIF(AO13:AY13,1)>0)+(COUNTIF(AO13:AY13,2)>0)+(COUNTIF(AO13:AY13,3)>0)+(COUNTIF(AO13:AY13,4)>0)+(COUNTIF(AO13:AY13,5)>0)+(COUNTIF(AO13:AY13,6)>0)+(COUNTIF(AO13:AY13,7)>0)+(COUNTIF(AO13:AY13,8)>0)+(COUNTIF(AO13:AY13,9)>0)+(COUNTIF(AO13:AY13,10)>0)+(COUNTIF(AO13:AY13,11)>0)+(COUNTIF(AO13:AY13,12)>0)+(COUNTIF(AO13:AY13,13)>0)+(COUNTIF(AO13:AY13,14)>0)+(COUNTIF(AO13:AY13,15)>0)+(COUNTIF(AO13:AY13,16)>0)+(COUNTIF(AO13:AY13,17)>0)+(COUNTIF(AO13:AY13,18)>0)+(COUNTIF(AO13:AY13,19)>0)+(COUNTIF(AO13:AY13,20)>0) | BY13: =IF(ISNUMBER(MATCH($B13,AO13:AY13,0)),1,0) | BZ13: =IF(BY13=1,0,BZ12+1) | CA13: =(COUNTIF(AZ13:BK13,1)>0)+(COUNTIF(AZ13:BK13,2)>0)+(COUNTIF(AZ13:BK13,3)>0)+(COUNTIF(AZ13:BK13,4)>0)+(COUNTIF(AZ13:BK13,5)>0)+(COUNTIF(AZ13:BK13,6)>0)+(COUNTIF(AZ13:BK13,7)>0)+(COUNTIF(AZ13:BK13,8)>0)+(COUNTIF(AZ13:BK13,9)>0)+(COUNTIF(AZ13:BK13,10)>0)+(COUNTIF(AZ13:BK13,11)>0)+(COUNTIF(AZ13:BK13,12)>0)+(COUNTIF(AZ13:BK13,13)>0)+(COUNTIF(AZ13:BK13,14)>0)+(COUNTIF(AZ13:BK13,15)>0)+(COUNTIF(AZ13:BK13,16)>0)+(COUNTIF(AZ13:BK13,17)>0)+(COUNTIF(AZ13:BK13,18)>0)+(COUNTIF(AZ13:BK13,19)>0)+(COUNTIF(AZ13:BK13,20)>0) | CB13: =IF(ISNUMBER(MATCH($B13,AZ13:BK13,0)),1,0) | CC13: =IF(CB13=1,0,CC12+1)
A14: 2026-05-05 19:00 | B14: 11 | C14: 16 | D14: 4 | E14: 17 | F14: 8 | G14: 2 | H14: 20 | I14: 8 | J14: 11 | K14: 7 | L14: 1 | M14: 2 | N14: 5 | O14: 7 | P14: 11 | Q14: 17 | R14: 6 | S14: 19 | T14: 13 | U14: 12 | V14: 16 | W14: 4 | X14: 17 | Y14: 8 | Z14: 2 | AA14: 20 | AB14: 11 | AC14: 7 | AD14: 1 | AE14: 16 | AF14: 4 | AG14: 17 | AH14: 8 | AI14: 2 | AJ14: 20 | AK14: 11 | AL14: 7 | AM14: 1 | AN14: 5 | AO14: 16 | AP14: 4 | AQ14: 17 | AR14: 8 | AS14: 2 | AT14: 20 | AU14: 11 | AV14: 7 | AW14: 1 | AX14: 5 | AY14: 6 | AZ14: 16 | BA14: 4 | BB14: 17 | BC14: 8 | BD14: 2 | BE14: 20 | BF14: 11 | BG14: 7 | BH14: 1 | BI14: 5 | BJ14: 6 | BK14: 19 | BL14: =(COUNTIF(C14:L14,1)>0)+(COUNTIF(C14:L14,2)>0)+(COUNTIF(C14:L14,3)>0)+(COUNTIF(C14:L14,4)>0)+(COUNTIF(C14:L14,5)>0)+(COUNTIF(C14:L14,6)>0)+(COUNTIF(C14:L14,7)>0)+(COUNTIF(C14:L14,8)>0)+(COUNTIF(C14:L14,9)>0)+(COUNTIF(C14:L14,10)>0)+(COUNTIF(C14:L14,11)>0)+(COUNTIF(C14:L14,12)>0)+(COUNTIF(C14:L14,13)>0)+(COUNTIF(C14:L14,14)>0)+(COUNTIF(C14:L14,15)>0)+(COUNTIF(C14:L14,16)>0)+(COUNTIF(C14:L14,17)>0)+(COUNTIF(C14:L14,18)>0)+(COUNTIF(C14:L14,19)>0)+(COUNTIF(C14:L14,20)>0) | BM14: =IF(ISNUMBER(MATCH($B14,C14:L14,0)),1,0) | BN14: =IF(BM14=1,0,BN13+1) | BO14: =(COUNTIF(M14:U14,1)>0)+(COUNTIF(M14:U14,2)>0)+(COUNTIF(M14:U14,3)>0)+(COUNTIF(M14:U14,4)>0)+(COUNTIF(M14:U14,5)>0)+(COUNTIF(M14:U14,6)>0)+(COUNTIF(M14:U14,7)>0)+(COUNTIF(M14:U14,8)>0)+(COUNTIF(M14:U14,9)>0)+(COUNTIF(M14:U14,10)>0)+(COUNTIF(M14:U14,11)>0)+(COUNTIF(M14:U14,12)>0)+(COUNTIF(M14:U14,13)>0)+(COUNTIF(M14:U14,14)>0)+(COUNTIF(M14:U14,15)>0)+(COUNTIF(M14:U14,16)>0)+(COUNTIF(M14:U14,17)>0)+(COUNTIF(M14:U14,18)>0)+(COUNTIF(M14:U14,19)>0)+(COUNTIF(M14:U14,20)>0) | BP14: =IF(ISNUMBER(MATCH($B14,M14:U14,0)),1,0) | BQ14: =IF(BP14=1,0,BQ13+1) | BR14: =(COUNTIF(V14:AD14,1)>0)+(COUNTIF(V14:AD14,2)>0)+(COUNTIF(V14:AD14,3)>0)+(COUNTIF(V14:AD14,4)>0)+(COUNTIF(V14:AD14,5)>0)+(COUNTIF(V14:AD14,6)>0)+(COUNTIF(V14:AD14,7)>0)+(COUNTIF(V14:AD14,8)>0)+(COUNTIF(V14:AD14,9)>0)+(COUNTIF(V14:AD14,10)>0)+(COUNTIF(V14:AD14,11)>0)+(COUNTIF(V14:AD14,12)>0)+(COUNTIF(V14:AD14,13)>0)+(COUNTIF(V14:AD14,14)>0)+(COUNTIF(V14:AD14,15)>0)+(COUNTIF(V14:AD14,16)>0)+(COUNTIF(V14:AD14,17)>0)+(COUNTIF(V14:AD14,18)>0)+(COUNTIF(V14:AD14,19)>0)+(COUNTIF(V14:AD14,20)>0) | BS14: =IF(ISNUMBER(MATCH($B14,V14:AD14,0)),1,0) | BT14: =IF(BS14=1,0,BT13+1) | BU14: =(COUNTIF(AE14:AN14,1)>0)+(COUNTIF(AE14:AN14,2)>0)+(COUNTIF(AE14:AN14,3)>0)+(COUNTIF(AE14:AN14,4)>0)+(COUNTIF(AE14:AN14,5)>0)+(COUNTIF(AE14:AN14,6)>0)+(COUNTIF(AE14:AN14,7)>0)+(COUNTIF(AE14:AN14,8)>0)+(COUNTIF(AE14:AN14,9)>0)+(COUNTIF(AE14:AN14,10)>0)+(COUNTIF(AE14:AN14,11)>0)+(COUNTIF(AE14:AN14,12)>0)+(COUNTIF(AE14:AN14,13)>0)+(COUNTIF(AE14:AN14,14)>0)+(COUNTIF(AE14:AN14,15)>0)+(COUNTIF(AE14:AN14,16)>0)+(COUNTIF(AE14:AN14,17)>0)+(COUNTIF(AE14:AN14,18)>0)+(COUNTIF(AE14:AN14,19)>0)+(COUNTIF(AE14:AN14,20)>0) | BV14: =IF(ISNUMBER(MATCH($B14,AE14:AN14,0)),1,0) | BW14: =IF(BV14=1,0,BW13+1) | BX14: =(COUNTIF(AO14:AY14,1)>0)+(COUNTIF(AO14:AY14,2)>0)+(COUNTIF(AO14:AY14,3)>0)+(COUNTIF(AO14:AY14,4)>0)+(COUNTIF(AO14:AY14,5)>0)+(COUNTIF(AO14:AY14,6)>0)+(COUNTIF(AO14:AY14,7)>0)+(COUNTIF(AO14:AY14,8)>0)+(COUNTIF(AO14:AY14,9)>0)+(COUNTIF(AO14:AY14,10)>0)+(COUNTIF(AO14:AY14,11)>0)+(COUNTIF(AO14:AY14,12)>0)+(COUNTIF(AO14:AY14,13)>0)+(COUNTIF(AO14:AY14,14)>0)+(COUNTIF(AO14:AY14,15)>0)+(COUNTIF(AO14:AY14,16)>0)+(COUNTIF(AO14:AY14,17)>0)+(COUNTIF(AO14:AY14,18)>0)+(COUNTIF(AO14:AY14,19)>0)+(COUNTIF(AO14:AY14,20)>0) | BY14: =IF(ISNUMBER(MATCH($B14,AO14:AY14,0)),1,0) | BZ14: =IF(BY14=1,0,BZ13+1) | CA14: =(COUNTIF(AZ14:BK14,1)>0)+(COUNTIF(AZ14:BK14,2)>0)+(COUNTIF(AZ14:BK14,3)>0)+(COUNTIF(AZ14:BK14,4)>0)+(COUNTIF(AZ14:BK14,5)>0)+(COUNTIF(AZ14:BK14,6)>0)+(COUNTIF(AZ14:BK14,7)>0)+(COUNTIF(AZ14:BK14,8)>0)+(COUNTIF(AZ14:BK14,9)>0)+(COUNTIF(AZ14:BK14,10)>0)+(COUNTIF(AZ14:BK14,11)>0)+(COUNTIF(AZ14:BK14,12)>0)+(COUNTIF(AZ14:BK14,13)>0)+(COUNTIF(AZ14:BK14,14)>0)+(COUNTIF(AZ14:BK14,15)>0)+(COUNTIF(AZ14:BK14,16)>0)+(COUNTIF(AZ14:BK14,17)>0)+(COUNTIF(AZ14:BK14,18)>0)+(COUNTIF(AZ14:BK14,19)>0)+(COUNTIF(AZ14:BK14,20)>0) | CB14: =IF(ISNUMBER(MATCH($B14,AZ14:BK14,0)),1,0) | CC14: =IF(CB14=1,0,CC13+1)
A15: 2026-05-05 20:00 | B15: 11 | C15: 7 | D15: 11 | E15: 1 | F15: 13 | G15: 13 | H15: 9 | I15: 18 | J15: 2 | K15: 8 | L15: 13 | M15: 8 | N15: 13 | O15: 6 | P15: 2 | Q15: 3 | R15: 20 | S15: 4 | T15: 19 | U15: 18 | V15: 7 | W15: 11 | X15: 1 | Y15: 13 | Z15: 9 | AA15: 18 | AB15: 2 | AC15: 8 | AD15: 6 | AE15: 7 | AF15: 11 | AG15: 1 | AH15: 13 | AI15: 9 | AJ15: 18 | AK15: 2 | AL15: 8 | AM15: 6 | AN15: 3 | AO15: 7 | AP15: 11 | AQ15: 1 | AR15: 13 | AS15: 9 | AT15: 18 | AU15: 2 | AV15: 8 | AW15: 6 | AX15: 3 | AY15: 20 | AZ15: 7 | BA15: 11 | BB15: 1 | BC15: 13 | BD15: 9 | BE15: 18 | BF15: 2 | BG15: 8 | BH15: 6 | BI15: 3 | BJ15: 20 | BK15: 4 | BL15: =(COUNTIF(C15:L15,1)>0)+(COUNTIF(C15:L15,2)>0)+(COUNTIF(C15:L15,3)>0)+(COUNTIF(C15:L15,4)>0)+(COUNTIF(C15:L15,5)>0)+(COUNTIF(C15:L15,6)>0)+(COUNTIF(C15:L15,7)>0)+(COUNTIF(C15:L15,8)>0)+(COUNTIF(C15:L15,9)>0)+(COUNTIF(C15:L15,10)>0)+(COUNTIF(C15:L15,11)>0)+(COUNTIF(C15:L15,12)>0)+(COUNTIF(C15:L15,13)>0)+(COUNTIF(C15:L15,14)>0)+(COUNTIF(C15:L15,15)>0)+(COUNTIF(C15:L15,16)>0)+(COUNTIF(C15:L15,17)>0)+(COUNTIF(C15:L15,18)>0)+(COUNTIF(C15:L15,19)>0)+(COUNTIF(C15:L15,20)>0) | BM15: =IF(ISNUMBER(MATCH($B15,C15:L15,0)),1,0) | BN15: =IF(BM15=1,0,BN14+1) | BO15: =(COUNTIF(M15:U15,1)>0)+(COUNTIF(M15:U15,2)>0)+(COUNTIF(M15:U15,3)>0)+(COUNTIF(M15:U15,4)>0)+(COUNTIF(M15:U15,5)>0)+(COUNTIF(M15:U15,6)>0)+(COUNTIF(M15:U15,7)>0)+(COUNTIF(M15:U15,8)>0)+(COUNTIF(M15:U15,9)>0)+(COUNTIF(M15:U15,10)>0)+(COUNTIF(M15:U15,11)>0)+(COUNTIF(M15:U15,12)>0)+(COUNTIF(M15:U15,13)>0)+(COUNTIF(M15:U15,14)>0)+(COUNTIF(M15:U15,15)>0)+(COUNTIF(M15:U15,16)>0)+(COUNTIF(M15:U15,17)>0)+(COUNTIF(M15:U15,18)>0)+(COUNTIF(M15:U15,19)>0)+(COUNTIF(M15:U15,20)>0) | BP15: =IF(ISNUMBER(MATCH($B15,M15:U15,0)),1,0) | BQ15: =IF(BP15=1,0,BQ14+1) | BR15: =(COUNTIF(V15:AD15,1)>0)+(COUNTIF(V15:AD15,2)>0)+(COUNTIF(V15:AD15,3)>0)+(COUNTIF(V15:AD15,4)>0)+(COUNTIF(V15:AD15,5)>0)+(COUNTIF(V15:AD15,6)>0)+(COUNTIF(V15:AD15,7)>0)+(COUNTIF(V15:AD15,8)>0)+(COUNTIF(V15:AD15,9)>0)+(COUNTIF(V15:AD15,10)>0)+(COUNTIF(V15:AD15,11)>0)+(COUNTIF(V15:AD15,12)>0)+(COUNTIF(V15:AD15,13)>0)+(COUNTIF(V15:AD15,14)>0)+(COUNTIF(V15:AD15,15)>0)+(COUNTIF(V15:AD15,16)>0)+(COUNTIF(V15:AD15,17)>0)+(COUNTIF(V15:AD15,18)>0)+(COUNTIF(V15:AD15,19)>0)+(COUNTIF(V15:AD15,20)>0) | BS15: =IF(ISNUMBER(MATCH($B15,V15:AD15,0)),1,0) | BT15: =IF(BS15=1,0,BT14+1) | BU15: =(COUNTIF(AE15:AN15,1)>0)+(COUNTIF(AE15:AN15,2)>0)+(COUNTIF(AE15:AN15,3)>0)+(COUNTIF(AE15:AN15,4)>0)+(COUNTIF(AE15:AN15,5)>0)+(COUNTIF(AE15:AN15,6)>0)+(COUNTIF(AE15:AN15,7)>0)+(COUNTIF(AE15:AN15,8)>0)+(COUNTIF(AE15:AN15,9)>0)+(COUNTIF(AE15:AN15,10)>0)+(COUNTIF(AE15:AN15,11)>0)+(COUNTIF(AE15:AN15,12)>0)+(COUNTIF(AE15:AN15,13)>0)+(COUNTIF(AE15:AN15,14)>0)+(COUNTIF(AE15:AN15,15)>0)+(COUNTIF(AE15:AN15,16)>0)+(COUNTIF(AE15:AN15,17)>0)+(COUNTIF(AE15:AN15,18)>0)+(COUNTIF(AE15:AN15,19)>0)+(COUNTIF(AE15:AN15,20)>0) | BV15: =IF(ISNUMBER(MATCH($B15,AE15:AN15,0)),1,0) | BW15: =IF(BV15=1,0,BW14+1) | BX15: =(COUNTIF(AO15:AY15,1)>0)+(COUNTIF(AO15:AY15,2)>0)+(COUNTIF(AO15:AY15,3)>0)+(COUNTIF(AO15:AY15,4)>0)+(COUNTIF(AO15:AY15,5)>0)+(COUNTIF(AO15:AY15,6)>0)+(COUNTIF(AO15:AY15,7)>0)+(COUNTIF(AO15:AY15,8)>0)+(COUNTIF(AO15:AY15,9)>0)+(COUNTIF(AO15:AY15,10)>0)+(COUNTIF(AO15:AY15,11)>0)+(COUNTIF(AO15:AY15,12)>0)+(COUNTIF(AO15:AY15,13)>0)+(COUNTIF(AO15:AY15,14)>0)+(COUNTIF(AO15:AY15,15)>0)+(COUNTIF(AO15:AY15,16)>0)+(COUNTIF(AO15:AY15,17)>0)+(COUNTIF(AO15:AY15,18)>0)+(COUNTIF(AO15:AY15,19)>0)+(COUNTIF(AO15:AY15,20)>0) | BY15: =IF(ISNUMBER(MATCH($B15,AO15:AY15,0)),1,0) | BZ15: =IF(BY15=1,0,BZ14+1) | CA15: =(COUNTIF(AZ15:BK15,1)>0)+(COUNTIF(AZ15:BK15,2)>0)+(COUNTIF(AZ15:BK15,3)>0)+(COUNTIF(AZ15:BK15,4)>0)+(COUNTIF(AZ15:BK15,5)>0)+(COUNTIF(AZ15:BK15,6)>0)+(COUNTIF(AZ15:BK15,7)>0)+(COUNTIF(AZ15:BK15,8)>0)+(COUNTIF(AZ15:BK15,9)>0)+(COUNTIF(AZ15:BK15,10)>0)+(COUNTIF(AZ15:BK15,11)>0)+(COUNTIF(AZ15:BK15,12)>0)+(COUNTIF(AZ15:BK15,13)>0)+(COUNTIF(AZ15:BK15,14)>0)+(COUNTIF(AZ15:BK15,15)>0)+(COUNTIF(AZ15:BK15,16)>0)+(COUNTIF(AZ15:BK15,17)>0)+(COUNTIF(AZ15:BK15,18)>0)+(COUNTIF(AZ15:BK15,19)>0)+(COUNTIF(AZ15:BK15,20)>0) | CB15: =IF(ISNUMBER(MATCH($B15,AZ15:BK15,0)),1,0) | CC15: =IF(CB15=1,0,CC14+1)
